[2025-04-10T06:55:17.353+0000] {local_task_job_runner.py:123} INFO - ::group::Pre task execution logs
[2025-04-10T06:55:17.464+0000] {taskinstance.py:2614} INFO - Dependencies all met for dep_context=non-requeueable deps ti=<TaskInstance: beer_data_processing.create_fact_table manual__2025-04-10T06:51:59.609521+00:00 [queued]>
[2025-04-10T06:55:17.513+0000] {taskinstance.py:2614} INFO - Dependencies all met for dep_context=requeueable deps ti=<TaskInstance: beer_data_processing.create_fact_table manual__2025-04-10T06:51:59.609521+00:00 [queued]>
[2025-04-10T06:55:17.514+0000] {taskinstance.py:2867} INFO - Starting attempt 4 of 6
[2025-04-10T06:55:17.565+0000] {taskinstance.py:2890} INFO - Executing <Task(PythonOperator): create_fact_table> on 2025-04-10 06:51:59.609521+00:00
[2025-04-10T06:55:17.623+0000] {standard_task_runner.py:104} INFO - Running: ['***', 'tasks', 'run', 'beer_data_processing', 'create_fact_table', 'manual__2025-04-10T06:51:59.609521+00:00', '--job-id', '114', '--raw', '--subdir', 'DAGS_FOLDER/beer_data_processing_dag.py', '--cfg-path', '/tmp/tmpt_n34gmi']
[2025-04-10T06:55:17.627+0000] {standard_task_runner.py:105} INFO - Job 114: Subtask create_fact_table
[2025-04-10T06:55:17.636+0000] {logging_mixin.py:190} WARNING - /home/***/.local/lib/python3.12/site-packages/***/task/task_runner/standard_task_runner.py:70 DeprecationWarning: This process (pid=19679) is multi-threaded, use of fork() may lead to deadlocks in the child.
[2025-04-10T06:55:17.638+0000] {standard_task_runner.py:72} INFO - Started process 19816 to run task
[2025-04-10T06:55:17.871+0000] {task_command.py:467} INFO - Running <TaskInstance: beer_data_processing.create_fact_table manual__2025-04-10T06:51:59.609521+00:00 [running]> on host 893b969cc7b0
[2025-04-10T06:55:18.285+0000] {taskinstance.py:3134} INFO - Exporting env vars: AIRFLOW_CTX_DAG_OWNER='***' AIRFLOW_CTX_DAG_ID='beer_data_processing' AIRFLOW_CTX_TASK_ID='create_fact_table' AIRFLOW_CTX_EXECUTION_DATE='2025-04-10T06:51:59.609521+00:00' AIRFLOW_CTX_TRY_NUMBER='4' AIRFLOW_CTX_DAG_RUN_ID='manual__2025-04-10T06:51:59.609521+00:00'
[2025-04-10T06:55:18.289+0000] {logging_mixin.py:190} INFO - Task instance is in running state
[2025-04-10T06:55:18.292+0000] {logging_mixin.py:190} INFO -  Previous state of the Task instance: queued
[2025-04-10T06:55:18.298+0000] {logging_mixin.py:190} INFO - Current task name:create_fact_table state:running start_date:2025-04-10 06:55:17.466606+00:00
[2025-04-10T06:55:18.301+0000] {logging_mixin.py:190} INFO - Dag name:beer_data_processing and current dag run status:running
[2025-04-10T06:55:18.303+0000] {taskinstance.py:732} INFO - ::endgroup::
[2025-04-10T06:55:18.695+0000] {logging_mixin.py:190} WARNING - /opt/***/dags/beer_data_processing_dag.py:190 FutureWarning: Passing literal json to 'read_json' is deprecated and will be removed in a future version. To read from a literal string, wrap it in a 'StringIO' object.
[2025-04-10T06:55:20.354+0000] {base.py:84} INFO - Retrieving connection 'postgres_conn'
[2025-04-10T06:55:20.442+0000] {taskinstance.py:3313} ERROR - Task failed with exception
Traceback (most recent call last):
  File "/home/airflow/.local/lib/python3.12/site-packages/airflow/models/taskinstance.py", line 768, in _execute_task
    result = _execute_callable(context=context, **execute_callable_kwargs)
             ^^^^^^^^^^^^^^^^^^^^^^^^^^^^^^^^^^^^^^^^^^^^^^^^^^^^^^^^^^^^^
  File "/home/airflow/.local/lib/python3.12/site-packages/airflow/models/taskinstance.py", line 734, in _execute_callable
    return ExecutionCallableRunner(
           ^^^^^^^^^^^^^^^^^^^^^^^^
  File "/home/airflow/.local/lib/python3.12/site-packages/airflow/utils/operator_helpers.py", line 252, in run
    return self.func(*args, **kwargs)
           ^^^^^^^^^^^^^^^^^^^^^^^^^^
  File "/home/airflow/.local/lib/python3.12/site-packages/airflow/models/baseoperator.py", line 424, in wrapper
    return func(self, *args, **kwargs)
           ^^^^^^^^^^^^^^^^^^^^^^^^^^^
  File "/home/airflow/.local/lib/python3.12/site-packages/airflow/operators/python.py", line 238, in execute
    return_value = self.execute_callable()
                   ^^^^^^^^^^^^^^^^^^^^^^^
  File "/home/airflow/.local/lib/python3.12/site-packages/airflow/operators/python.py", line 256, in execute_callable
    return runner.run(*self.op_args, **self.op_kwargs)
           ^^^^^^^^^^^^^^^^^^^^^^^^^^^^^^^^^^^^^^^^^^^
  File "/home/airflow/.local/lib/python3.12/site-packages/airflow/utils/operator_helpers.py", line 252, in run
    return self.func(*args, **kwargs)
           ^^^^^^^^^^^^^^^^^^^^^^^^^^
  File "/opt/airflow/dags/beer_data_processing_dag.py", line 260, in create_fact_table
    cursor.execute(query, values)
psycopg2.errors.UndefinedColumn: column "review_aroma" of relation "fact_beer" does not exist
LINE 2: ...sweet, sour, salty, fruits, hoppy, spices, malty, review_aro...
                                                             ^

[2025-04-10T06:55:20.518+0000] {logging_mixin.py:190} INFO - Task instance in failure state
[2025-04-10T06:55:20.520+0000] {logging_mixin.py:190} INFO - Task start:2025-04-10 06:55:17.466606+00:00 end:2025-04-10 06:55:20.516322+00:00 duration:3.049716
[2025-04-10T06:55:20.521+0000] {logging_mixin.py:190} INFO - Task:<Task(PythonOperator): create_fact_table> dag:<DAG: beer_data_processing> dagrun:<DagRun beer_data_processing @ 2025-04-10 06:51:59.609521+00:00: manual__2025-04-10T06:51:59.609521+00:00, state:running, queued_at: 2025-04-10 06:51:59.852373+00:00. externally triggered: True>
[2025-04-10T06:55:20.522+0000] {logging_mixin.py:190} INFO - Failure caused by column "review_aroma" of relation "fact_beer" does not exist
LINE 2: ...sweet, sour, salty, fruits, hoppy, spices, malty, review_aro...
                                                             ^
[2025-04-10T06:55:20.523+0000] {taskinstance.py:1226} INFO - Marking task as UP_FOR_RETRY. dag_id=beer_data_processing, task_id=create_fact_table, run_id=manual__2025-04-10T06:51:59.609521+00:00, execution_date=20250410T065159, start_date=20250410T065517, end_date=20250410T065520
[2025-04-10T06:55:20.874+0000] {taskinstance.py:341} INFO - ::group::Post task execution logs
[2025-04-10T06:55:20.876+0000] {standard_task_runner.py:124} ERROR - Failed to execute job 114 for task create_fact_table (column "review_aroma" of relation "fact_beer" does not exist
LINE 2: ...sweet, sour, salty, fruits, hoppy, spices, malty, review_aro...
                                                             ^
; 19816)
Traceback (most recent call last):
  File "/home/airflow/.local/lib/python3.12/site-packages/airflow/task/task_runner/standard_task_runner.py", line 117, in _start_by_fork
    ret = args.func(args, dag=self.dag)
          ^^^^^^^^^^^^^^^^^^^^^^^^^^^^^
  File "/home/airflow/.local/lib/python3.12/site-packages/airflow/cli/cli_config.py", line 49, in command
    return func(*args, **kwargs)
           ^^^^^^^^^^^^^^^^^^^^^
  File "/home/airflow/.local/lib/python3.12/site-packages/airflow/utils/cli.py", line 116, in wrapper
    return f(*args, **kwargs)
           ^^^^^^^^^^^^^^^^^^
  File "/home/airflow/.local/lib/python3.12/site-packages/airflow/cli/commands/task_command.py", line 483, in task_run
    task_return_code = _run_task_by_selected_method(args, _dag, ti)
                       ^^^^^^^^^^^^^^^^^^^^^^^^^^^^^^^^^^^^^^^^^^^^
  File "/home/airflow/.local/lib/python3.12/site-packages/airflow/cli/commands/task_command.py", line 256, in _run_task_by_selected_method
    return _run_raw_task(args, ti)
           ^^^^^^^^^^^^^^^^^^^^^^^
  File "/home/airflow/.local/lib/python3.12/site-packages/airflow/cli/commands/task_command.py", line 341, in _run_raw_task
    return ti._run_raw_task(
           ^^^^^^^^^^^^^^^^^
  File "/home/airflow/.local/lib/python3.12/site-packages/airflow/utils/session.py", line 97, in wrapper
    return func(*args, session=session, **kwargs)
           ^^^^^^^^^^^^^^^^^^^^^^^^^^^^^^^^^^^^^^
  File "/home/airflow/.local/lib/python3.12/site-packages/airflow/models/taskinstance.py", line 3006, in _run_raw_task
    return _run_raw_task(
           ^^^^^^^^^^^^^^
  File "/home/airflow/.local/lib/python3.12/site-packages/airflow/models/taskinstance.py", line 274, in _run_raw_task
    TaskInstance._execute_task_with_callbacks(
  File "/home/airflow/.local/lib/python3.12/site-packages/airflow/models/taskinstance.py", line 3161, in _execute_task_with_callbacks
    result = self._execute_task(context, task_orig)
             ^^^^^^^^^^^^^^^^^^^^^^^^^^^^^^^^^^^^^^
  File "/home/airflow/.local/lib/python3.12/site-packages/airflow/models/taskinstance.py", line 3185, in _execute_task
    return _execute_task(self, context, task_orig)
           ^^^^^^^^^^^^^^^^^^^^^^^^^^^^^^^^^^^^^^^
  File "/home/airflow/.local/lib/python3.12/site-packages/airflow/models/taskinstance.py", line 768, in _execute_task
    result = _execute_callable(context=context, **execute_callable_kwargs)
             ^^^^^^^^^^^^^^^^^^^^^^^^^^^^^^^^^^^^^^^^^^^^^^^^^^^^^^^^^^^^^
  File "/home/airflow/.local/lib/python3.12/site-packages/airflow/models/taskinstance.py", line 734, in _execute_callable
    return ExecutionCallableRunner(
           ^^^^^^^^^^^^^^^^^^^^^^^^
  File "/home/airflow/.local/lib/python3.12/site-packages/airflow/utils/operator_helpers.py", line 252, in run
    return self.func(*args, **kwargs)
           ^^^^^^^^^^^^^^^^^^^^^^^^^^
  File "/home/airflow/.local/lib/python3.12/site-packages/airflow/models/baseoperator.py", line 424, in wrapper
    return func(self, *args, **kwargs)
           ^^^^^^^^^^^^^^^^^^^^^^^^^^^
  File "/home/airflow/.local/lib/python3.12/site-packages/airflow/operators/python.py", line 238, in execute
    return_value = self.execute_callable()
                   ^^^^^^^^^^^^^^^^^^^^^^^
  File "/home/airflow/.local/lib/python3.12/site-packages/airflow/operators/python.py", line 256, in execute_callable
    return runner.run(*self.op_args, **self.op_kwargs)
           ^^^^^^^^^^^^^^^^^^^^^^^^^^^^^^^^^^^^^^^^^^^
  File "/home/airflow/.local/lib/python3.12/site-packages/airflow/utils/operator_helpers.py", line 252, in run
    return self.func(*args, **kwargs)
           ^^^^^^^^^^^^^^^^^^^^^^^^^^
  File "/opt/airflow/dags/beer_data_processing_dag.py", line 260, in create_fact_table
    cursor.execute(query, values)
psycopg2.errors.UndefinedColumn: column "review_aroma" of relation "fact_beer" does not exist
LINE 2: ...sweet, sour, salty, fruits, hoppy, spices, malty, review_aro...
                                                             ^

[2025-04-10T06:55:20.920+0000] {local_task_job_runner.py:266} INFO - Task exited with return code 1
[2025-04-10T06:55:20.982+0000] {taskinstance.py:3901} INFO - 0 downstream tasks scheduled from follow-on schedule check
[2025-04-10T06:55:21.058+0000] {local_task_job_runner.py:245} INFO - ::endgroup::
