[2025-04-10T09:28:09.098+0000] {local_task_job_runner.py:123} INFO - ::group::Pre task execution logs
[2025-04-10T09:28:09.212+0000] {taskinstance.py:2614} INFO - Dependencies all met for dep_context=non-requeueable deps ti=<TaskInstance: beer_data_processing.create_dim_style manual__2025-04-10T09:22:57.738854+00:00 [queued]>
[2025-04-10T09:28:09.253+0000] {taskinstance.py:2614} INFO - Dependencies all met for dep_context=requeueable deps ti=<TaskInstance: beer_data_processing.create_dim_style manual__2025-04-10T09:22:57.738854+00:00 [queued]>
[2025-04-10T09:28:09.260+0000] {taskinstance.py:2867} INFO - Starting attempt 4 of 6
[2025-04-10T09:28:09.334+0000] {taskinstance.py:2890} INFO - Executing <Task(PythonOperator): create_dim_style> on 2025-04-10 09:22:57.738854+00:00
[2025-04-10T09:28:09.453+0000] {standard_task_runner.py:104} INFO - Running: ['***', 'tasks', 'run', 'beer_data_processing', 'create_dim_style', 'manual__2025-04-10T09:22:57.738854+00:00', '--job-id', '164', '--raw', '--subdir', 'DAGS_FOLDER/beer_data_processing_dag.py', '--cfg-path', '/tmp/tmpyb2zta99']
[2025-04-10T09:28:09.462+0000] {standard_task_runner.py:105} INFO - Job 164: Subtask create_dim_style
[2025-04-10T09:28:09.481+0000] {logging_mixin.py:190} WARNING - /home/***/.local/lib/python3.12/site-packages/***/task/task_runner/standard_task_runner.py:70 DeprecationWarning: This process (pid=13395) is multi-threaded, use of fork() may lead to deadlocks in the child.
[2025-04-10T09:28:09.494+0000] {standard_task_runner.py:72} INFO - Started process 13464 to run task
[2025-04-10T09:28:09.947+0000] {task_command.py:467} INFO - Running <TaskInstance: beer_data_processing.create_dim_style manual__2025-04-10T09:22:57.738854+00:00 [running]> on host abcc0ba2292b
[2025-04-10T09:28:10.540+0000] {taskinstance.py:3134} INFO - Exporting env vars: AIRFLOW_CTX_DAG_OWNER='***' AIRFLOW_CTX_DAG_ID='beer_data_processing' AIRFLOW_CTX_TASK_ID='create_dim_style' AIRFLOW_CTX_EXECUTION_DATE='2025-04-10T09:22:57.738854+00:00' AIRFLOW_CTX_TRY_NUMBER='4' AIRFLOW_CTX_DAG_RUN_ID='manual__2025-04-10T09:22:57.738854+00:00'
[2025-04-10T09:28:10.547+0000] {logging_mixin.py:190} INFO - Task instance is in running state
[2025-04-10T09:28:10.550+0000] {logging_mixin.py:190} INFO -  Previous state of the Task instance: queued
[2025-04-10T09:28:10.552+0000] {logging_mixin.py:190} INFO - Current task name:create_dim_style state:running start_date:2025-04-10 09:28:09.214454+00:00
[2025-04-10T09:28:10.555+0000] {logging_mixin.py:190} INFO - Dag name:beer_data_processing and current dag run status:running
[2025-04-10T09:28:10.557+0000] {taskinstance.py:732} INFO - ::endgroup::
[2025-04-10T09:28:11.223+0000] {logging_mixin.py:190} WARNING - /opt/***/dags/beer_data_processing_dag.py:108 FutureWarning: Passing literal json to 'read_json' is deprecated and will be removed in a future version. To read from a literal string, wrap it in a 'StringIO' object.
[2025-04-10T09:28:11.975+0000] {base.py:84} INFO - Retrieving connection 'postgres_conn'
[2025-04-10T09:28:12.089+0000] {taskinstance.py:3313} ERROR - Task failed with exception
Traceback (most recent call last):
  File "/home/airflow/.local/lib/python3.12/site-packages/airflow/models/taskinstance.py", line 768, in _execute_task
    result = _execute_callable(context=context, **execute_callable_kwargs)
             ^^^^^^^^^^^^^^^^^^^^^^^^^^^^^^^^^^^^^^^^^^^^^^^^^^^^^^^^^^^^^
  File "/home/airflow/.local/lib/python3.12/site-packages/airflow/models/taskinstance.py", line 734, in _execute_callable
    return ExecutionCallableRunner(
           ^^^^^^^^^^^^^^^^^^^^^^^^
  File "/home/airflow/.local/lib/python3.12/site-packages/airflow/utils/operator_helpers.py", line 252, in run
    return self.func(*args, **kwargs)
           ^^^^^^^^^^^^^^^^^^^^^^^^^^
  File "/home/airflow/.local/lib/python3.12/site-packages/airflow/models/baseoperator.py", line 424, in wrapper
    return func(self, *args, **kwargs)
           ^^^^^^^^^^^^^^^^^^^^^^^^^^^
  File "/home/airflow/.local/lib/python3.12/site-packages/airflow/operators/python.py", line 238, in execute
    return_value = self.execute_callable()
                   ^^^^^^^^^^^^^^^^^^^^^^^
  File "/home/airflow/.local/lib/python3.12/site-packages/airflow/operators/python.py", line 256, in execute_callable
    return runner.run(*self.op_args, **self.op_kwargs)
           ^^^^^^^^^^^^^^^^^^^^^^^^^^^^^^^^^^^^^^^^^^^
  File "/home/airflow/.local/lib/python3.12/site-packages/airflow/utils/operator_helpers.py", line 252, in run
    return self.func(*args, **kwargs)
           ^^^^^^^^^^^^^^^^^^^^^^^^^^
  File "/opt/airflow/dags/beer_data_processing_dag.py", line 125, in create_dim_style
    cursor.execute(
psycopg2.errors.UniqueViolation: duplicate key value violates unique constraint "dim_style_pkey"
DETAIL:  Key (style_id)=(1) already exists.

[2025-04-10T09:28:12.380+0000] {logging_mixin.py:190} INFO - Task instance in failure state
[2025-04-10T09:28:12.381+0000] {logging_mixin.py:190} INFO - Task start:2025-04-10 09:28:09.214454+00:00 end:2025-04-10 09:28:12.374794+00:00 duration:3.16034
[2025-04-10T09:28:12.385+0000] {logging_mixin.py:190} INFO - Task:<Task(PythonOperator): create_dim_style> dag:<DAG: beer_data_processing> dagrun:<DagRun beer_data_processing @ 2025-04-10 09:22:57.738854+00:00: manual__2025-04-10T09:22:57.738854+00:00, state:running, queued_at: 2025-04-10 09:22:58.209788+00:00. externally triggered: True>
[2025-04-10T09:28:12.388+0000] {logging_mixin.py:190} INFO - Failure caused by duplicate key value violates unique constraint "dim_style_pkey"
DETAIL:  Key (style_id)=(1) already exists.
[2025-04-10T09:28:12.393+0000] {taskinstance.py:1226} INFO - Marking task as UP_FOR_RETRY. dag_id=beer_data_processing, task_id=create_dim_style, run_id=manual__2025-04-10T09:22:57.738854+00:00, execution_date=20250410T092257, start_date=20250410T092809, end_date=20250410T092812
[2025-04-10T09:28:12.678+0000] {taskinstance.py:341} INFO - ::group::Post task execution logs
[2025-04-10T09:28:12.686+0000] {standard_task_runner.py:124} ERROR - Failed to execute job 164 for task create_dim_style (duplicate key value violates unique constraint "dim_style_pkey"
DETAIL:  Key (style_id)=(1) already exists.
; 13464)
Traceback (most recent call last):
  File "/home/airflow/.local/lib/python3.12/site-packages/airflow/task/task_runner/standard_task_runner.py", line 117, in _start_by_fork
    ret = args.func(args, dag=self.dag)
          ^^^^^^^^^^^^^^^^^^^^^^^^^^^^^
  File "/home/airflow/.local/lib/python3.12/site-packages/airflow/cli/cli_config.py", line 49, in command
    return func(*args, **kwargs)
           ^^^^^^^^^^^^^^^^^^^^^
  File "/home/airflow/.local/lib/python3.12/site-packages/airflow/utils/cli.py", line 116, in wrapper
    return f(*args, **kwargs)
           ^^^^^^^^^^^^^^^^^^
  File "/home/airflow/.local/lib/python3.12/site-packages/airflow/cli/commands/task_command.py", line 483, in task_run
    task_return_code = _run_task_by_selected_method(args, _dag, ti)
                       ^^^^^^^^^^^^^^^^^^^^^^^^^^^^^^^^^^^^^^^^^^^^
  File "/home/airflow/.local/lib/python3.12/site-packages/airflow/cli/commands/task_command.py", line 256, in _run_task_by_selected_method
    return _run_raw_task(args, ti)
           ^^^^^^^^^^^^^^^^^^^^^^^
  File "/home/airflow/.local/lib/python3.12/site-packages/airflow/cli/commands/task_command.py", line 341, in _run_raw_task
    return ti._run_raw_task(
           ^^^^^^^^^^^^^^^^^
  File "/home/airflow/.local/lib/python3.12/site-packages/airflow/utils/session.py", line 97, in wrapper
    return func(*args, session=session, **kwargs)
           ^^^^^^^^^^^^^^^^^^^^^^^^^^^^^^^^^^^^^^
  File "/home/airflow/.local/lib/python3.12/site-packages/airflow/models/taskinstance.py", line 3006, in _run_raw_task
    return _run_raw_task(
           ^^^^^^^^^^^^^^
  File "/home/airflow/.local/lib/python3.12/site-packages/airflow/models/taskinstance.py", line 274, in _run_raw_task
    TaskInstance._execute_task_with_callbacks(
  File "/home/airflow/.local/lib/python3.12/site-packages/airflow/models/taskinstance.py", line 3161, in _execute_task_with_callbacks
    result = self._execute_task(context, task_orig)
             ^^^^^^^^^^^^^^^^^^^^^^^^^^^^^^^^^^^^^^
  File "/home/airflow/.local/lib/python3.12/site-packages/airflow/models/taskinstance.py", line 3185, in _execute_task
    return _execute_task(self, context, task_orig)
           ^^^^^^^^^^^^^^^^^^^^^^^^^^^^^^^^^^^^^^^
  File "/home/airflow/.local/lib/python3.12/site-packages/airflow/models/taskinstance.py", line 768, in _execute_task
    result = _execute_callable(context=context, **execute_callable_kwargs)
             ^^^^^^^^^^^^^^^^^^^^^^^^^^^^^^^^^^^^^^^^^^^^^^^^^^^^^^^^^^^^^
  File "/home/airflow/.local/lib/python3.12/site-packages/airflow/models/taskinstance.py", line 734, in _execute_callable
    return ExecutionCallableRunner(
           ^^^^^^^^^^^^^^^^^^^^^^^^
  File "/home/airflow/.local/lib/python3.12/site-packages/airflow/utils/operator_helpers.py", line 252, in run
    return self.func(*args, **kwargs)
           ^^^^^^^^^^^^^^^^^^^^^^^^^^
  File "/home/airflow/.local/lib/python3.12/site-packages/airflow/models/baseoperator.py", line 424, in wrapper
    return func(self, *args, **kwargs)
           ^^^^^^^^^^^^^^^^^^^^^^^^^^^
  File "/home/airflow/.local/lib/python3.12/site-packages/airflow/operators/python.py", line 238, in execute
    return_value = self.execute_callable()
                   ^^^^^^^^^^^^^^^^^^^^^^^
  File "/home/airflow/.local/lib/python3.12/site-packages/airflow/operators/python.py", line 256, in execute_callable
    return runner.run(*self.op_args, **self.op_kwargs)
           ^^^^^^^^^^^^^^^^^^^^^^^^^^^^^^^^^^^^^^^^^^^
  File "/home/airflow/.local/lib/python3.12/site-packages/airflow/utils/operator_helpers.py", line 252, in run
    return self.func(*args, **kwargs)
           ^^^^^^^^^^^^^^^^^^^^^^^^^^
  File "/opt/airflow/dags/beer_data_processing_dag.py", line 125, in create_dim_style
    cursor.execute(
psycopg2.errors.UniqueViolation: duplicate key value violates unique constraint "dim_style_pkey"
DETAIL:  Key (style_id)=(1) already exists.

[2025-04-10T09:28:12.895+0000] {local_task_job_runner.py:266} INFO - Task exited with return code 1
[2025-04-10T09:28:13.073+0000] {taskinstance.py:3901} INFO - 0 downstream tasks scheduled from follow-on schedule check
[2025-04-10T09:28:13.081+0000] {local_task_job_runner.py:245} INFO - ::endgroup::
