[2025-04-09T17:03:45.853+0000] {local_task_job_runner.py:123} INFO - ::group::Pre task execution logs
[2025-04-09T17:03:45.887+0000] {taskinstance.py:2614} INFO - Dependencies all met for dep_context=non-requeueable deps ti=<TaskInstance: beer_data_processing.check_file_exists manual__2025-04-09T16:59:48.093895+00:00 [queued]>
[2025-04-09T17:03:45.901+0000] {taskinstance.py:2614} INFO - Dependencies all met for dep_context=requeueable deps ti=<TaskInstance: beer_data_processing.check_file_exists manual__2025-04-09T16:59:48.093895+00:00 [queued]>
[2025-04-09T17:03:45.903+0000] {taskinstance.py:2867} INFO - Starting attempt 5 of 6
[2025-04-09T17:03:45.978+0000] {taskinstance.py:2890} INFO - Executing <Task(FileSensor): check_file_exists> on 2025-04-09 16:59:48.093895+00:00
[2025-04-09T17:03:46.068+0000] {standard_task_runner.py:104} INFO - Running: ['***', 'tasks', 'run', 'beer_data_processing', 'check_file_exists', 'manual__2025-04-09T16:59:48.093895+00:00', '--job-id', '29', '--raw', '--subdir', 'DAGS_FOLDER/beer_data_processing_dag.py', '--cfg-path', '/tmp/tmpk2ooba63']
[2025-04-09T17:03:46.070+0000] {standard_task_runner.py:105} INFO - Job 29: Subtask check_file_exists
[2025-04-09T17:03:46.074+0000] {logging_mixin.py:190} WARNING - /home/***/.local/lib/python3.12/site-packages/***/task/task_runner/standard_task_runner.py:70 DeprecationWarning: This process (pid=4785) is multi-threaded, use of fork() may lead to deadlocks in the child.
[2025-04-09T17:03:46.076+0000] {standard_task_runner.py:72} INFO - Started process 4871 to run task
[2025-04-09T17:03:46.255+0000] {task_command.py:467} INFO - Running <TaskInstance: beer_data_processing.check_file_exists manual__2025-04-09T16:59:48.093895+00:00 [running]> on host edb8bc0f15af
[2025-04-09T17:03:46.437+0000] {taskinstance.py:3134} INFO - Exporting env vars: AIRFLOW_CTX_DAG_OWNER='***' AIRFLOW_CTX_DAG_ID='beer_data_processing' AIRFLOW_CTX_TASK_ID='check_file_exists' AIRFLOW_CTX_EXECUTION_DATE='2025-04-09T16:59:48.093895+00:00' AIRFLOW_CTX_TRY_NUMBER='5' AIRFLOW_CTX_DAG_RUN_ID='manual__2025-04-09T16:59:48.093895+00:00'
[2025-04-09T17:03:46.462+0000] {logging_mixin.py:190} INFO - Task instance is in running state
[2025-04-09T17:03:46.464+0000] {logging_mixin.py:190} INFO -  Previous state of the Task instance: queued
[2025-04-09T17:03:46.465+0000] {logging_mixin.py:190} INFO - Current task name:check_file_exists state:running start_date:2025-04-09 17:03:45.888737+00:00
[2025-04-09T17:03:46.466+0000] {logging_mixin.py:190} INFO - Dag name:beer_data_processing and current dag run status:running
[2025-04-09T17:03:46.468+0000] {taskinstance.py:732} INFO - ::endgroup::
[2025-04-09T17:03:46.469+0000] {baseoperator.py:423} WARNING - FileSensor.execute cannot be called outside TaskInstance!
[2025-04-09T17:03:46.514+0000] {taskinstance.py:3313} ERROR - Task failed with exception
Traceback (most recent call last):
  File "/home/airflow/.local/lib/python3.12/site-packages/airflow/models/taskinstance.py", line 768, in _execute_task
    result = _execute_callable(context=context, **execute_callable_kwargs)
             ^^^^^^^^^^^^^^^^^^^^^^^^^^^^^^^^^^^^^^^^^^^^^^^^^^^^^^^^^^^^^
  File "/home/airflow/.local/lib/python3.12/site-packages/airflow/models/taskinstance.py", line 734, in _execute_callable
    return ExecutionCallableRunner(
           ^^^^^^^^^^^^^^^^^^^^^^^^
  File "/home/airflow/.local/lib/python3.12/site-packages/airflow/utils/operator_helpers.py", line 252, in run
    return self.func(*args, **kwargs)
           ^^^^^^^^^^^^^^^^^^^^^^^^^^
  File "/home/airflow/.local/lib/python3.12/site-packages/airflow/models/baseoperator.py", line 424, in wrapper
    return func(self, *args, **kwargs)
           ^^^^^^^^^^^^^^^^^^^^^^^^^^^
  File "/home/airflow/.local/lib/python3.12/site-packages/airflow/sensors/filesystem.py", line 123, in execute
    super().execute(context=context)
  File "/home/airflow/.local/lib/python3.12/site-packages/airflow/models/baseoperator.py", line 424, in wrapper
    return func(self, *args, **kwargs)
           ^^^^^^^^^^^^^^^^^^^^^^^^^^^
  File "/home/airflow/.local/lib/python3.12/site-packages/airflow/sensors/base.py", line 309, in execute
    raise e
  File "/home/airflow/.local/lib/python3.12/site-packages/airflow/sensors/base.py", line 289, in execute
    poke_return = self.poke(context)
                  ^^^^^^^^^^^^^^^^^^
  File "/home/airflow/.local/lib/python3.12/site-packages/airflow/sensors/filesystem.py", line 109, in poke
    self.log.info("Poking for file %s", self.path)
                                        ^^^^^^^^^
  File "/usr/local/lib/python3.12/functools.py", line 998, in __get__
    val = self.func(instance)
          ^^^^^^^^^^^^^^^^^^^
  File "/home/airflow/.local/lib/python3.12/site-packages/airflow/sensors/filesystem.py", line 103, in path
    hook = FSHook(self.fs_conn_id)
           ^^^^^^^^^^^^^^^^^^^^^^^
  File "/home/airflow/.local/lib/python3.12/site-packages/airflow/hooks/filesystem.py", line 64, in __init__
    conn = self.get_connection(fs_conn_id)
           ^^^^^^^^^^^^^^^^^^^^^^^^^^^^^^^
  File "/home/airflow/.local/lib/python3.12/site-packages/airflow/hooks/base.py", line 83, in get_connection
    conn = Connection.get_connection_from_secrets(conn_id)
           ^^^^^^^^^^^^^^^^^^^^^^^^^^^^^^^^^^^^^^^^^^^^^^^
  File "/home/airflow/.local/lib/python3.12/site-packages/airflow/models/connection.py", line 537, in get_connection_from_secrets
    raise AirflowNotFoundException(f"The conn_id `{conn_id}` isn't defined")
airflow.exceptions.AirflowNotFoundException: The conn_id `fs_default` isn't defined
[2025-04-09T17:03:46.551+0000] {logging_mixin.py:190} INFO - Task instance in failure state
[2025-04-09T17:03:46.552+0000] {logging_mixin.py:190} INFO - Task start:2025-04-09 17:03:45.888737+00:00 end:2025-04-09 17:03:46.547193+00:00 duration:0.658456
[2025-04-09T17:03:46.553+0000] {logging_mixin.py:190} INFO - Task:<Task(FileSensor): check_file_exists> dag:<DAG: beer_data_processing> dagrun:<DagRun beer_data_processing @ 2025-04-09 16:59:48.093895+00:00: manual__2025-04-09T16:59:48.093895+00:00, state:running, queued_at: 2025-04-09 16:59:48.433977+00:00. externally triggered: True>
[2025-04-09T17:03:46.554+0000] {logging_mixin.py:190} INFO - Failure caused by The conn_id `fs_default` isn't defined
[2025-04-09T17:03:46.555+0000] {taskinstance.py:1226} INFO - Marking task as UP_FOR_RETRY. dag_id=beer_data_processing, task_id=check_file_exists, run_id=manual__2025-04-09T16:59:48.093895+00:00, execution_date=20250409T165948, start_date=20250409T170345, end_date=20250409T170346
[2025-04-09T17:03:46.707+0000] {taskinstance.py:341} INFO - ::group::Post task execution logs
[2025-04-09T17:03:46.709+0000] {standard_task_runner.py:124} ERROR - Failed to execute job 29 for task check_file_exists (The conn_id `fs_default` isn't defined; 4871)
Traceback (most recent call last):
  File "/home/airflow/.local/lib/python3.12/site-packages/airflow/task/task_runner/standard_task_runner.py", line 117, in _start_by_fork
    ret = args.func(args, dag=self.dag)
          ^^^^^^^^^^^^^^^^^^^^^^^^^^^^^
  File "/home/airflow/.local/lib/python3.12/site-packages/airflow/cli/cli_config.py", line 49, in command
    return func(*args, **kwargs)
           ^^^^^^^^^^^^^^^^^^^^^
  File "/home/airflow/.local/lib/python3.12/site-packages/airflow/utils/cli.py", line 116, in wrapper
    return f(*args, **kwargs)
           ^^^^^^^^^^^^^^^^^^
  File "/home/airflow/.local/lib/python3.12/site-packages/airflow/cli/commands/task_command.py", line 483, in task_run
    task_return_code = _run_task_by_selected_method(args, _dag, ti)
                       ^^^^^^^^^^^^^^^^^^^^^^^^^^^^^^^^^^^^^^^^^^^^
  File "/home/airflow/.local/lib/python3.12/site-packages/airflow/cli/commands/task_command.py", line 256, in _run_task_by_selected_method
    return _run_raw_task(args, ti)
           ^^^^^^^^^^^^^^^^^^^^^^^
  File "/home/airflow/.local/lib/python3.12/site-packages/airflow/cli/commands/task_command.py", line 341, in _run_raw_task
    return ti._run_raw_task(
           ^^^^^^^^^^^^^^^^^
  File "/home/airflow/.local/lib/python3.12/site-packages/airflow/utils/session.py", line 97, in wrapper
    return func(*args, session=session, **kwargs)
           ^^^^^^^^^^^^^^^^^^^^^^^^^^^^^^^^^^^^^^
  File "/home/airflow/.local/lib/python3.12/site-packages/airflow/models/taskinstance.py", line 3006, in _run_raw_task
    return _run_raw_task(
           ^^^^^^^^^^^^^^
  File "/home/airflow/.local/lib/python3.12/site-packages/airflow/models/taskinstance.py", line 274, in _run_raw_task
    TaskInstance._execute_task_with_callbacks(
  File "/home/airflow/.local/lib/python3.12/site-packages/airflow/models/taskinstance.py", line 3161, in _execute_task_with_callbacks
    result = self._execute_task(context, task_orig)
             ^^^^^^^^^^^^^^^^^^^^^^^^^^^^^^^^^^^^^^
  File "/home/airflow/.local/lib/python3.12/site-packages/airflow/models/taskinstance.py", line 3185, in _execute_task
    return _execute_task(self, context, task_orig)
           ^^^^^^^^^^^^^^^^^^^^^^^^^^^^^^^^^^^^^^^
  File "/home/airflow/.local/lib/python3.12/site-packages/airflow/models/taskinstance.py", line 768, in _execute_task
    result = _execute_callable(context=context, **execute_callable_kwargs)
             ^^^^^^^^^^^^^^^^^^^^^^^^^^^^^^^^^^^^^^^^^^^^^^^^^^^^^^^^^^^^^
  File "/home/airflow/.local/lib/python3.12/site-packages/airflow/models/taskinstance.py", line 734, in _execute_callable
    return ExecutionCallableRunner(
           ^^^^^^^^^^^^^^^^^^^^^^^^
  File "/home/airflow/.local/lib/python3.12/site-packages/airflow/utils/operator_helpers.py", line 252, in run
    return self.func(*args, **kwargs)
           ^^^^^^^^^^^^^^^^^^^^^^^^^^
  File "/home/airflow/.local/lib/python3.12/site-packages/airflow/models/baseoperator.py", line 424, in wrapper
    return func(self, *args, **kwargs)
           ^^^^^^^^^^^^^^^^^^^^^^^^^^^
  File "/home/airflow/.local/lib/python3.12/site-packages/airflow/sensors/filesystem.py", line 123, in execute
    super().execute(context=context)
  File "/home/airflow/.local/lib/python3.12/site-packages/airflow/models/baseoperator.py", line 424, in wrapper
    return func(self, *args, **kwargs)
           ^^^^^^^^^^^^^^^^^^^^^^^^^^^
  File "/home/airflow/.local/lib/python3.12/site-packages/airflow/sensors/base.py", line 309, in execute
    raise e
  File "/home/airflow/.local/lib/python3.12/site-packages/airflow/sensors/base.py", line 289, in execute
    poke_return = self.poke(context)
                  ^^^^^^^^^^^^^^^^^^
  File "/home/airflow/.local/lib/python3.12/site-packages/airflow/sensors/filesystem.py", line 109, in poke
    self.log.info("Poking for file %s", self.path)
                                        ^^^^^^^^^
  File "/usr/local/lib/python3.12/functools.py", line 998, in __get__
    val = self.func(instance)
          ^^^^^^^^^^^^^^^^^^^
  File "/home/airflow/.local/lib/python3.12/site-packages/airflow/sensors/filesystem.py", line 103, in path
    hook = FSHook(self.fs_conn_id)
           ^^^^^^^^^^^^^^^^^^^^^^^
  File "/home/airflow/.local/lib/python3.12/site-packages/airflow/hooks/filesystem.py", line 64, in __init__
    conn = self.get_connection(fs_conn_id)
           ^^^^^^^^^^^^^^^^^^^^^^^^^^^^^^^
  File "/home/airflow/.local/lib/python3.12/site-packages/airflow/hooks/base.py", line 83, in get_connection
    conn = Connection.get_connection_from_secrets(conn_id)
           ^^^^^^^^^^^^^^^^^^^^^^^^^^^^^^^^^^^^^^^^^^^^^^^
  File "/home/airflow/.local/lib/python3.12/site-packages/airflow/models/connection.py", line 537, in get_connection_from_secrets
    raise AirflowNotFoundException(f"The conn_id `{conn_id}` isn't defined")
airflow.exceptions.AirflowNotFoundException: The conn_id `fs_default` isn't defined
[2025-04-09T17:03:46.780+0000] {local_task_job_runner.py:266} INFO - Task exited with return code 1
[2025-04-09T17:03:46.826+0000] {taskinstance.py:3901} INFO - 0 downstream tasks scheduled from follow-on schedule check
[2025-04-09T17:03:46.895+0000] {local_task_job_runner.py:245} INFO - ::endgroup::
