[2025-04-17T11:50:21.118+0000] {local_task_job_runner.py:123} INFO - ::group::Pre task execution logs
[2025-04-17T11:50:24.540+0000] {taskinstance.py:2614} INFO - Dependencies all met for dep_context=non-requeueable deps ti=<TaskInstance: beer_data_processing.check_file_exists scheduled__2025-04-17T06:00:00+00:00 [queued]>
[2025-04-17T11:50:24.639+0000] {taskinstance.py:2614} INFO - Dependencies all met for dep_context=requeueable deps ti=<TaskInstance: beer_data_processing.check_file_exists scheduled__2025-04-17T06:00:00+00:00 [queued]>
[2025-04-17T11:50:24.646+0000] {taskinstance.py:2867} INFO - Starting attempt 1 of 6
[2025-04-17T11:50:24.920+0000] {taskinstance.py:2890} INFO - Executing <Task(FileSensor): check_file_exists> on 2025-04-17 06:00:00+00:00
[2025-04-17T11:50:25.583+0000] {standard_task_runner.py:104} INFO - Running: ['***', 'tasks', 'run', 'beer_data_processing', 'check_file_exists', 'scheduled__2025-04-17T06:00:00+00:00', '--job-id', '899', '--raw', '--subdir', 'DAGS_FOLDER/beer_data_processing_dag.py', '--cfg-path', '/tmp/tmph_j4yxzx']
[2025-04-17T11:50:25.677+0000] {standard_task_runner.py:105} INFO - Job 899: Subtask check_file_exists
[2025-04-17T11:50:26.373+0000] {logging_mixin.py:190} WARNING - /home/***/.local/lib/python3.12/site-packages/***/task/task_runner/standard_task_runner.py:70 DeprecationWarning: This process (pid=39553) is multi-threaded, use of fork() may lead to deadlocks in the child.
[2025-04-17T11:50:26.388+0000] {standard_task_runner.py:72} INFO - Started process 40034 to run task
[2025-04-17T11:50:27.086+0000] {task_command.py:467} INFO - Running <TaskInstance: beer_data_processing.check_file_exists scheduled__2025-04-17T06:00:00+00:00 [running]> on host a0d0456bae2c
[2025-04-17T11:50:39.974+0000] {job.py:229} INFO - Heartbeat recovered after 22.25 seconds
[2025-04-17T11:50:41.553+0000] {taskinstance.py:3134} INFO - Exporting env vars: AIRFLOW_CTX_DAG_OWNER='***' AIRFLOW_CTX_DAG_ID='beer_data_processing' AIRFLOW_CTX_TASK_ID='check_file_exists' AIRFLOW_CTX_EXECUTION_DATE='2025-04-17T06:00:00+00:00' AIRFLOW_CTX_TRY_NUMBER='1' AIRFLOW_CTX_DAG_RUN_ID='scheduled__2025-04-17T06:00:00+00:00'
[2025-04-17T11:50:41.654+0000] {logging_mixin.py:190} INFO - Task instance is in running state
[2025-04-17T11:50:41.660+0000] {logging_mixin.py:190} INFO -  Previous state of the Task instance: queued
[2025-04-17T11:50:41.662+0000] {logging_mixin.py:190} INFO - Current task name:check_file_exists state:running start_date:2025-04-17 11:50:24.542197+00:00
[2025-04-17T11:50:41.666+0000] {logging_mixin.py:190} INFO - Dag name:beer_data_processing and current dag run status:running
[2025-04-17T11:50:41.669+0000] {taskinstance.py:732} INFO - ::endgroup::
[2025-04-17T11:50:41.674+0000] {baseoperator.py:423} WARNING - FileSensor.execute cannot be called outside TaskInstance!
[2025-04-17T11:50:41.786+0000] {base.py:84} INFO - Retrieving connection 'dataset_folder'
[2025-04-17T11:50:41.797+0000] {filesystem.py:109} INFO - Poking for file /opt/***/dags/data/beer_profile_and_ratings.csv
[2025-04-17T11:50:41.857+0000] {filesystem.py:113} INFO - Found File /opt/***/dags/data/beer_profile_and_ratings.csv last modified: 20250416145823
[2025-04-17T11:50:41.878+0000] {base.py:339} INFO - Success criteria met. Exiting.
[2025-04-17T11:50:41.916+0000] {filesystem.py:109} INFO - Poking for file /opt/***/dags/data/beer_profile_and_ratings.csv
[2025-04-17T11:50:41.942+0000] {filesystem.py:113} INFO - Found File /opt/***/dags/data/beer_profile_and_ratings.csv last modified: 20250416145823
[2025-04-17T11:50:42.101+0000] {taskinstance.py:341} INFO - ::group::Post task execution logs
[2025-04-17T11:50:42.110+0000] {taskinstance.py:353} INFO - Marking task as SUCCESS. dag_id=beer_data_processing, task_id=check_file_exists, run_id=scheduled__2025-04-17T06:00:00+00:00, execution_date=20250417T060000, start_date=20250417T115024, end_date=20250417T115042
[2025-04-17T11:51:14.763+0000] {job.py:229} INFO - Heartbeat recovered after 16.13 seconds
[2025-04-17T11:51:35.129+0000] {job.py:229} INFO - Heartbeat recovered after 40.86 seconds
[2025-04-17T11:51:47.733+0000] {job.py:229} INFO - Heartbeat recovered after 15.11 seconds
[2025-04-17T11:51:58.722+0000] {job.py:229} INFO - Heartbeat recovered after 11.06 seconds
[2025-04-17T11:52:16.939+0000] {job.py:229} INFO - Heartbeat recovered after 20.30 seconds
[2025-04-17T11:54:08.319+0000] {job.py:239} ERROR - Job heartbeat failed with error
Traceback (most recent call last):
  File "/home/airflow/.local/lib/python3.12/site-packages/sqlalchemy/engine/base.py", line 3371, in _wrap_pool_connect
    return fn()
           ^^^^
  File "/home/airflow/.local/lib/python3.12/site-packages/sqlalchemy/pool/base.py", line 327, in connect
    return _ConnectionFairy._checkout(self)
           ^^^^^^^^^^^^^^^^^^^^^^^^^^^^^^^^
  File "/home/airflow/.local/lib/python3.12/site-packages/sqlalchemy/pool/base.py", line 894, in _checkout
    fairy = _ConnectionRecord.checkout(pool)
            ^^^^^^^^^^^^^^^^^^^^^^^^^^^^^^^^
  File "/home/airflow/.local/lib/python3.12/site-packages/sqlalchemy/pool/base.py", line 493, in checkout
    rec = pool._do_get()
          ^^^^^^^^^^^^^^
  File "/home/airflow/.local/lib/python3.12/site-packages/sqlalchemy/pool/impl.py", line 256, in _do_get
    return self._create_connection()
           ^^^^^^^^^^^^^^^^^^^^^^^^^
  File "/home/airflow/.local/lib/python3.12/site-packages/sqlalchemy/pool/base.py", line 273, in _create_connection
    return _ConnectionRecord(self)
           ^^^^^^^^^^^^^^^^^^^^^^^
  File "/home/airflow/.local/lib/python3.12/site-packages/sqlalchemy/pool/base.py", line 388, in __init__
    self.__connect()
  File "/home/airflow/.local/lib/python3.12/site-packages/sqlalchemy/pool/base.py", line 690, in __connect
    with util.safe_reraise():
         ^^^^^^^^^^^^^^^^^^^
  File "/home/airflow/.local/lib/python3.12/site-packages/sqlalchemy/util/langhelpers.py", line 70, in __exit__
    compat.raise_(
  File "/home/airflow/.local/lib/python3.12/site-packages/sqlalchemy/util/compat.py", line 211, in raise_
    raise exception
  File "/home/airflow/.local/lib/python3.12/site-packages/sqlalchemy/pool/base.py", line 686, in __connect
    self.dbapi_connection = connection = pool._invoke_creator(self)
                                         ^^^^^^^^^^^^^^^^^^^^^^^^^^
  File "/home/airflow/.local/lib/python3.12/site-packages/sqlalchemy/engine/create.py", line 574, in connect
    return dialect.connect(*cargs, **cparams)
           ^^^^^^^^^^^^^^^^^^^^^^^^^^^^^^^^^^
  File "/home/airflow/.local/lib/python3.12/site-packages/sqlalchemy/engine/default.py", line 598, in connect
    return self.dbapi.connect(*cargs, **cparams)
           ^^^^^^^^^^^^^^^^^^^^^^^^^^^^^^^^^^^^^
  File "/home/airflow/.local/lib/python3.12/site-packages/psycopg2/__init__.py", line 122, in connect
    conn = _connect(dsn, connection_factory=connection_factory, **kwasync)
           ^^^^^^^^^^^^^^^^^^^^^^^^^^^^^^^^^^^^^^^^^^^^^^^^^^^^^^^^^^^^^^^
psycopg2.OperationalError: could not translate host name "postgres" to address: Temporary failure in name resolution


The above exception was the direct cause of the following exception:

Traceback (most recent call last):
  File "/home/airflow/.local/lib/python3.12/site-packages/airflow/jobs/job.py", line 207, in heartbeat
    self._merge_from(Job._fetch_from_db(self, session))
                     ^^^^^^^^^^^^^^^^^^^^^^^^^^^^^^^^^
  File "/home/airflow/.local/lib/python3.12/site-packages/airflow/api_internal/internal_api_call.py", line 166, in wrapper
    return func(*args, **kwargs)
           ^^^^^^^^^^^^^^^^^^^^^
  File "/home/airflow/.local/lib/python3.12/site-packages/airflow/utils/session.py", line 94, in wrapper
    return func(*args, **kwargs)
           ^^^^^^^^^^^^^^^^^^^^^
  File "/home/airflow/.local/lib/python3.12/site-packages/airflow/utils/retries.py", line 93, in wrapped_function
    for attempt in run_with_db_retries(max_retries=retries, logger=logger, **retry_kwargs):
                   ^^^^^^^^^^^^^^^^^^^^^^^^^^^^^^^^^^^^^^^^^^^^^^^^^^^^^^^^^^^^^^^^^^^^^^^
  File "/home/airflow/.local/lib/python3.12/site-packages/tenacity/__init__.py", line 443, in __iter__
    do = self.iter(retry_state=retry_state)
         ^^^^^^^^^^^^^^^^^^^^^^^^^^^^^^^^^^
  File "/home/airflow/.local/lib/python3.12/site-packages/tenacity/__init__.py", line 376, in iter
    result = action(retry_state)
             ^^^^^^^^^^^^^^^^^^^
  File "/home/airflow/.local/lib/python3.12/site-packages/tenacity/__init__.py", line 418, in exc_check
    raise retry_exc.reraise()
          ^^^^^^^^^^^^^^^^^^^
  File "/home/airflow/.local/lib/python3.12/site-packages/tenacity/__init__.py", line 185, in reraise
    raise self.last_attempt.result()
          ^^^^^^^^^^^^^^^^^^^^^^^^^^
  File "/usr/local/lib/python3.12/concurrent/futures/_base.py", line 449, in result
    return self.__get_result()
           ^^^^^^^^^^^^^^^^^^^
  File "/usr/local/lib/python3.12/concurrent/futures/_base.py", line 401, in __get_result
    raise self._exception
  File "/home/airflow/.local/lib/python3.12/site-packages/airflow/utils/retries.py", line 102, in wrapped_function
    return func(*args, **kwargs)
           ^^^^^^^^^^^^^^^^^^^^^
  File "/home/airflow/.local/lib/python3.12/site-packages/airflow/jobs/job.py", line 335, in _fetch_from_db
    session.merge(job)
  File "/home/airflow/.local/lib/python3.12/site-packages/sqlalchemy/orm/session.py", line 3056, in merge
    return self._merge(
           ^^^^^^^^^^^^
  File "/home/airflow/.local/lib/python3.12/site-packages/sqlalchemy/orm/session.py", line 3136, in _merge
    merged = self.get(
             ^^^^^^^^^
  File "/home/airflow/.local/lib/python3.12/site-packages/sqlalchemy/orm/session.py", line 2853, in get
    return self._get_impl(
           ^^^^^^^^^^^^^^^
  File "/home/airflow/.local/lib/python3.12/site-packages/sqlalchemy/orm/session.py", line 2975, in _get_impl
    return db_load_fn(
           ^^^^^^^^^^^
  File "/home/airflow/.local/lib/python3.12/site-packages/sqlalchemy/orm/loading.py", line 530, in load_on_pk_identity
    session.execute(
  File "/home/airflow/.local/lib/python3.12/site-packages/sqlalchemy/orm/session.py", line 1716, in execute
    conn = self._connection_for_bind(bind)
           ^^^^^^^^^^^^^^^^^^^^^^^^^^^^^^^
  File "/home/airflow/.local/lib/python3.12/site-packages/sqlalchemy/orm/session.py", line 1555, in _connection_for_bind
    return self._transaction._connection_for_bind(
           ^^^^^^^^^^^^^^^^^^^^^^^^^^^^^^^^^^^^^^^
  File "/home/airflow/.local/lib/python3.12/site-packages/sqlalchemy/orm/session.py", line 750, in _connection_for_bind
    conn = bind.connect()
           ^^^^^^^^^^^^^^
  File "/home/airflow/.local/lib/python3.12/site-packages/sqlalchemy/future/engine.py", line 412, in connect
    return super(Engine, self).connect()
           ^^^^^^^^^^^^^^^^^^^^^^^^^^^^^
  File "/home/airflow/.local/lib/python3.12/site-packages/sqlalchemy/engine/base.py", line 3325, in connect
    return self._connection_cls(self, close_with_result=close_with_result)
           ^^^^^^^^^^^^^^^^^^^^^^^^^^^^^^^^^^^^^^^^^^^^^^^^^^^^^^^^^^^^^^^
  File "/home/airflow/.local/lib/python3.12/site-packages/sqlalchemy/engine/base.py", line 96, in __init__
    else engine.raw_connection()
         ^^^^^^^^^^^^^^^^^^^^^^^
  File "/home/airflow/.local/lib/python3.12/site-packages/sqlalchemy/engine/base.py", line 3404, in raw_connection
    return self._wrap_pool_connect(self.pool.connect, _connection)
           ^^^^^^^^^^^^^^^^^^^^^^^^^^^^^^^^^^^^^^^^^^^^^^^^^^^^^^^
  File "/home/airflow/.local/lib/python3.12/site-packages/sqlalchemy/engine/base.py", line 3374, in _wrap_pool_connect
    Connection._handle_dbapi_exception_noconnection(
  File "/home/airflow/.local/lib/python3.12/site-packages/sqlalchemy/engine/base.py", line 2208, in _handle_dbapi_exception_noconnection
    util.raise_(
  File "/home/airflow/.local/lib/python3.12/site-packages/sqlalchemy/util/compat.py", line 211, in raise_
    raise exception
  File "/home/airflow/.local/lib/python3.12/site-packages/sqlalchemy/engine/base.py", line 3371, in _wrap_pool_connect
    return fn()
           ^^^^
  File "/home/airflow/.local/lib/python3.12/site-packages/sqlalchemy/pool/base.py", line 327, in connect
    return _ConnectionFairy._checkout(self)
           ^^^^^^^^^^^^^^^^^^^^^^^^^^^^^^^^
  File "/home/airflow/.local/lib/python3.12/site-packages/sqlalchemy/pool/base.py", line 894, in _checkout
    fairy = _ConnectionRecord.checkout(pool)
            ^^^^^^^^^^^^^^^^^^^^^^^^^^^^^^^^
  File "/home/airflow/.local/lib/python3.12/site-packages/sqlalchemy/pool/base.py", line 493, in checkout
    rec = pool._do_get()
          ^^^^^^^^^^^^^^
  File "/home/airflow/.local/lib/python3.12/site-packages/sqlalchemy/pool/impl.py", line 256, in _do_get
    return self._create_connection()
           ^^^^^^^^^^^^^^^^^^^^^^^^^
  File "/home/airflow/.local/lib/python3.12/site-packages/sqlalchemy/pool/base.py", line 273, in _create_connection
    return _ConnectionRecord(self)
           ^^^^^^^^^^^^^^^^^^^^^^^
  File "/home/airflow/.local/lib/python3.12/site-packages/sqlalchemy/pool/base.py", line 388, in __init__
    self.__connect()
  File "/home/airflow/.local/lib/python3.12/site-packages/sqlalchemy/pool/base.py", line 690, in __connect
    with util.safe_reraise():
         ^^^^^^^^^^^^^^^^^^^
  File "/home/airflow/.local/lib/python3.12/site-packages/sqlalchemy/util/langhelpers.py", line 70, in __exit__
    compat.raise_(
  File "/home/airflow/.local/lib/python3.12/site-packages/sqlalchemy/util/compat.py", line 211, in raise_
    raise exception
  File "/home/airflow/.local/lib/python3.12/site-packages/sqlalchemy/pool/base.py", line 686, in __connect
    self.dbapi_connection = connection = pool._invoke_creator(self)
                                         ^^^^^^^^^^^^^^^^^^^^^^^^^^
  File "/home/airflow/.local/lib/python3.12/site-packages/sqlalchemy/engine/create.py", line 574, in connect
    return dialect.connect(*cargs, **cparams)
           ^^^^^^^^^^^^^^^^^^^^^^^^^^^^^^^^^^
  File "/home/airflow/.local/lib/python3.12/site-packages/sqlalchemy/engine/default.py", line 598, in connect
    return self.dbapi.connect(*cargs, **cparams)
           ^^^^^^^^^^^^^^^^^^^^^^^^^^^^^^^^^^^^^
  File "/home/airflow/.local/lib/python3.12/site-packages/psycopg2/__init__.py", line 122, in connect
    conn = _connect(dsn, connection_factory=connection_factory, **kwasync)
           ^^^^^^^^^^^^^^^^^^^^^^^^^^^^^^^^^^^^^^^^^^^^^^^^^^^^^^^^^^^^^^^
sqlalchemy.exc.OperationalError: (psycopg2.OperationalError) could not translate host name "postgres" to address: Temporary failure in name resolution

(Background on this error at: https://sqlalche.me/e/14/e3q8)
[2025-04-17T11:55:38.085+0000] {job.py:254} ERROR - Job heartbeat failed with error. Scheduler is in unhealthy state
[2025-04-17T11:55:52.524+0000] {job.py:229} INFO - Heartbeat recovered after 149.96 seconds
[2025-04-17T11:56:16.972+0000] {job.py:229} INFO - Heartbeat recovered after 11.72 seconds
[2025-04-17T11:56:39.488+0000] {job.py:229} INFO - Heartbeat recovered after 22.74 seconds
[2025-04-17T11:57:02.186+0000] {job.py:229} INFO - Heartbeat recovered after 15.75 seconds
[2025-04-17T11:57:28.533+0000] {job.py:229} INFO - Heartbeat recovered after 29.29 seconds
[2025-04-17T11:57:37.120+0000] {job.py:229} INFO - Heartbeat recovered after 11.48 seconds
[2025-04-17T11:58:22.554+0000] {job.py:229} INFO - Heartbeat recovered after 11.23 seconds
[2025-04-17T11:58:44.010+0000] {job.py:229} INFO - Heartbeat recovered after 12.28 seconds
[2025-04-17T11:59:30.395+0000] {job.py:229} INFO - Heartbeat recovered after 46.57 seconds
[2025-04-17T11:59:55.751+0000] {job.py:229} INFO - Heartbeat recovered after 29.29 seconds
[2025-04-17T12:01:15.142+0000] {logging_mixin.py:190} INFO - Task instance in success state
[2025-04-17T12:01:15.234+0000] {logging_mixin.py:190} INFO -  Previous state of the Task instance: running
[2025-04-17T12:01:15.241+0000] {logging_mixin.py:190} INFO - Dag name:beer_data_processing queued_at:2025-04-17 11:36:12.377924+00:00
[2025-04-17T12:01:15.247+0000] {logging_mixin.py:190} INFO - Task hostname:a0d0456bae2c operator:FileSensor
[2025-04-17T12:01:19.945+0000] {job.py:229} INFO - Heartbeat recovered after 42.89 seconds
[2025-04-17T12:01:21.518+0000] {local_task_job_runner.py:266} INFO - Task exited with return code 0
[2025-04-17T12:01:21.860+0000] {standard_task_runner.py:217} INFO - Process not found (most likely exited), stop collecting metrics
[2025-04-17T12:01:31.269+0000] {taskinstance.py:3901} INFO - 1 downstream tasks scheduled from follow-on schedule check
[2025-04-17T12:01:31.304+0000] {local_task_job_runner.py:245} INFO - ::endgroup::
