[2025-04-10T07:13:18.186+0000] {local_task_job_runner.py:123} INFO - ::group::Pre task execution logs
[2025-04-10T07:13:18.269+0000] {taskinstance.py:2614} INFO - Dependencies all met for dep_context=non-requeueable deps ti=<TaskInstance: beer_data_processing.create_fact_table manual__2025-04-10T07:10:12.640088+00:00 [queued]>
[2025-04-10T07:13:18.322+0000] {taskinstance.py:2614} INFO - Dependencies all met for dep_context=requeueable deps ti=<TaskInstance: beer_data_processing.create_fact_table manual__2025-04-10T07:10:12.640088+00:00 [queued]>
[2025-04-10T07:13:18.324+0000] {taskinstance.py:2867} INFO - Starting attempt 3 of 6
[2025-04-10T07:13:18.376+0000] {taskinstance.py:2890} INFO - Executing <Task(PythonOperator): create_fact_table> on 2025-04-10 07:10:12.640088+00:00
[2025-04-10T07:13:18.441+0000] {standard_task_runner.py:104} INFO - Running: ['***', 'tasks', 'run', 'beer_data_processing', 'create_fact_table', 'manual__2025-04-10T07:10:12.640088+00:00', '--job-id', '125', '--raw', '--subdir', 'DAGS_FOLDER/beer_data_processing_dag.py', '--cfg-path', '/tmp/tmprdh7rezp']
[2025-04-10T07:13:18.464+0000] {standard_task_runner.py:105} INFO - Job 125: Subtask create_fact_table
[2025-04-10T07:13:18.470+0000] {logging_mixin.py:190} WARNING - /home/***/.local/lib/python3.12/site-packages/***/task/task_runner/standard_task_runner.py:70 DeprecationWarning: This process (pid=28226) is multi-threaded, use of fork() may lead to deadlocks in the child.
[2025-04-10T07:13:18.475+0000] {standard_task_runner.py:72} INFO - Started process 28281 to run task
[2025-04-10T07:13:18.995+0000] {task_command.py:467} INFO - Running <TaskInstance: beer_data_processing.create_fact_table manual__2025-04-10T07:10:12.640088+00:00 [running]> on host 893b969cc7b0
[2025-04-10T07:13:19.570+0000] {taskinstance.py:3134} INFO - Exporting env vars: AIRFLOW_CTX_DAG_OWNER='***' AIRFLOW_CTX_DAG_ID='beer_data_processing' AIRFLOW_CTX_TASK_ID='create_fact_table' AIRFLOW_CTX_EXECUTION_DATE='2025-04-10T07:10:12.640088+00:00' AIRFLOW_CTX_TRY_NUMBER='3' AIRFLOW_CTX_DAG_RUN_ID='manual__2025-04-10T07:10:12.640088+00:00'
[2025-04-10T07:13:19.574+0000] {logging_mixin.py:190} INFO - Task instance is in running state
[2025-04-10T07:13:19.575+0000] {logging_mixin.py:190} INFO -  Previous state of the Task instance: queued
[2025-04-10T07:13:19.577+0000] {logging_mixin.py:190} INFO - Current task name:create_fact_table state:running start_date:2025-04-10 07:13:18.271307+00:00
[2025-04-10T07:13:19.578+0000] {logging_mixin.py:190} INFO - Dag name:beer_data_processing and current dag run status:running
[2025-04-10T07:13:19.579+0000] {taskinstance.py:732} INFO - ::endgroup::
[2025-04-10T07:13:19.892+0000] {logging_mixin.py:190} WARNING - /opt/***/dags/beer_data_processing_dag.py:190 FutureWarning: Passing literal json to 'read_json' is deprecated and will be removed in a future version. To read from a literal string, wrap it in a 'StringIO' object.
[2025-04-10T07:13:20.315+0000] {base.py:84} INFO - Retrieving connection 'postgres_conn'
[2025-04-10T07:13:20.391+0000] {taskinstance.py:3313} ERROR - Task failed with exception
Traceback (most recent call last):
  File "/home/airflow/.local/lib/python3.12/site-packages/airflow/models/taskinstance.py", line 768, in _execute_task
    result = _execute_callable(context=context, **execute_callable_kwargs)
             ^^^^^^^^^^^^^^^^^^^^^^^^^^^^^^^^^^^^^^^^^^^^^^^^^^^^^^^^^^^^^
  File "/home/airflow/.local/lib/python3.12/site-packages/airflow/models/taskinstance.py", line 734, in _execute_callable
    return ExecutionCallableRunner(
           ^^^^^^^^^^^^^^^^^^^^^^^^
  File "/home/airflow/.local/lib/python3.12/site-packages/airflow/utils/operator_helpers.py", line 252, in run
    return self.func(*args, **kwargs)
           ^^^^^^^^^^^^^^^^^^^^^^^^^^
  File "/home/airflow/.local/lib/python3.12/site-packages/airflow/models/baseoperator.py", line 424, in wrapper
    return func(self, *args, **kwargs)
           ^^^^^^^^^^^^^^^^^^^^^^^^^^^
  File "/home/airflow/.local/lib/python3.12/site-packages/airflow/operators/python.py", line 238, in execute
    return_value = self.execute_callable()
                   ^^^^^^^^^^^^^^^^^^^^^^^
  File "/home/airflow/.local/lib/python3.12/site-packages/airflow/operators/python.py", line 256, in execute_callable
    return runner.run(*self.op_args, **self.op_kwargs)
           ^^^^^^^^^^^^^^^^^^^^^^^^^^^^^^^^^^^^^^^^^^^
  File "/home/airflow/.local/lib/python3.12/site-packages/airflow/utils/operator_helpers.py", line 252, in run
    return self.func(*args, **kwargs)
           ^^^^^^^^^^^^^^^^^^^^^^^^^^
  File "/opt/airflow/dags/beer_data_processing_dag.py", line 260, in create_fact_table
    cursor.execute(query, values)
psycopg2.errors.UndefinedColumn: column "review_aroma" of relation "fact_beer" does not exist
LINE 2: ...sweet, sour, salty, fruits, hoppy, spices, malty, review_aro...
                                                             ^

[2025-04-10T07:13:20.448+0000] {logging_mixin.py:190} INFO - Task instance in failure state
[2025-04-10T07:13:20.450+0000] {logging_mixin.py:190} INFO - Task start:2025-04-10 07:13:18.271307+00:00 end:2025-04-10 07:13:20.447895+00:00 duration:2.176588
[2025-04-10T07:13:20.452+0000] {logging_mixin.py:190} INFO - Task:<Task(PythonOperator): create_fact_table> dag:<DAG: beer_data_processing> dagrun:<DagRun beer_data_processing @ 2025-04-10 07:10:12.640088+00:00: manual__2025-04-10T07:10:12.640088+00:00, state:running, queued_at: 2025-04-10 07:10:13.028340+00:00. externally triggered: True>
[2025-04-10T07:13:20.453+0000] {logging_mixin.py:190} INFO - Failure caused by column "review_aroma" of relation "fact_beer" does not exist
LINE 2: ...sweet, sour, salty, fruits, hoppy, spices, malty, review_aro...
                                                             ^
[2025-04-10T07:13:20.454+0000] {taskinstance.py:1226} INFO - Marking task as UP_FOR_RETRY. dag_id=beer_data_processing, task_id=create_fact_table, run_id=manual__2025-04-10T07:10:12.640088+00:00, execution_date=20250410T071012, start_date=20250410T071318, end_date=20250410T071320
[2025-04-10T07:13:20.534+0000] {taskinstance.py:341} INFO - ::group::Post task execution logs
[2025-04-10T07:13:20.535+0000] {standard_task_runner.py:124} ERROR - Failed to execute job 125 for task create_fact_table (column "review_aroma" of relation "fact_beer" does not exist
LINE 2: ...sweet, sour, salty, fruits, hoppy, spices, malty, review_aro...
                                                             ^
; 28281)
Traceback (most recent call last):
  File "/home/airflow/.local/lib/python3.12/site-packages/airflow/task/task_runner/standard_task_runner.py", line 117, in _start_by_fork
    ret = args.func(args, dag=self.dag)
          ^^^^^^^^^^^^^^^^^^^^^^^^^^^^^
  File "/home/airflow/.local/lib/python3.12/site-packages/airflow/cli/cli_config.py", line 49, in command
    return func(*args, **kwargs)
           ^^^^^^^^^^^^^^^^^^^^^
  File "/home/airflow/.local/lib/python3.12/site-packages/airflow/utils/cli.py", line 116, in wrapper
    return f(*args, **kwargs)
           ^^^^^^^^^^^^^^^^^^
  File "/home/airflow/.local/lib/python3.12/site-packages/airflow/cli/commands/task_command.py", line 483, in task_run
    task_return_code = _run_task_by_selected_method(args, _dag, ti)
                       ^^^^^^^^^^^^^^^^^^^^^^^^^^^^^^^^^^^^^^^^^^^^
  File "/home/airflow/.local/lib/python3.12/site-packages/airflow/cli/commands/task_command.py", line 256, in _run_task_by_selected_method
    return _run_raw_task(args, ti)
           ^^^^^^^^^^^^^^^^^^^^^^^
  File "/home/airflow/.local/lib/python3.12/site-packages/airflow/cli/commands/task_command.py", line 341, in _run_raw_task
    return ti._run_raw_task(
           ^^^^^^^^^^^^^^^^^
  File "/home/airflow/.local/lib/python3.12/site-packages/airflow/utils/session.py", line 97, in wrapper
    return func(*args, session=session, **kwargs)
           ^^^^^^^^^^^^^^^^^^^^^^^^^^^^^^^^^^^^^^
  File "/home/airflow/.local/lib/python3.12/site-packages/airflow/models/taskinstance.py", line 3006, in _run_raw_task
    return _run_raw_task(
           ^^^^^^^^^^^^^^
  File "/home/airflow/.local/lib/python3.12/site-packages/airflow/models/taskinstance.py", line 274, in _run_raw_task
    TaskInstance._execute_task_with_callbacks(
  File "/home/airflow/.local/lib/python3.12/site-packages/airflow/models/taskinstance.py", line 3161, in _execute_task_with_callbacks
    result = self._execute_task(context, task_orig)
             ^^^^^^^^^^^^^^^^^^^^^^^^^^^^^^^^^^^^^^
  File "/home/airflow/.local/lib/python3.12/site-packages/airflow/models/taskinstance.py", line 3185, in _execute_task
    return _execute_task(self, context, task_orig)
           ^^^^^^^^^^^^^^^^^^^^^^^^^^^^^^^^^^^^^^^
  File "/home/airflow/.local/lib/python3.12/site-packages/airflow/models/taskinstance.py", line 768, in _execute_task
    result = _execute_callable(context=context, **execute_callable_kwargs)
             ^^^^^^^^^^^^^^^^^^^^^^^^^^^^^^^^^^^^^^^^^^^^^^^^^^^^^^^^^^^^^
  File "/home/airflow/.local/lib/python3.12/site-packages/airflow/models/taskinstance.py", line 734, in _execute_callable
    return ExecutionCallableRunner(
           ^^^^^^^^^^^^^^^^^^^^^^^^
  File "/home/airflow/.local/lib/python3.12/site-packages/airflow/utils/operator_helpers.py", line 252, in run
    return self.func(*args, **kwargs)
           ^^^^^^^^^^^^^^^^^^^^^^^^^^
  File "/home/airflow/.local/lib/python3.12/site-packages/airflow/models/baseoperator.py", line 424, in wrapper
    return func(self, *args, **kwargs)
           ^^^^^^^^^^^^^^^^^^^^^^^^^^^
  File "/home/airflow/.local/lib/python3.12/site-packages/airflow/operators/python.py", line 238, in execute
    return_value = self.execute_callable()
                   ^^^^^^^^^^^^^^^^^^^^^^^
  File "/home/airflow/.local/lib/python3.12/site-packages/airflow/operators/python.py", line 256, in execute_callable
    return runner.run(*self.op_args, **self.op_kwargs)
           ^^^^^^^^^^^^^^^^^^^^^^^^^^^^^^^^^^^^^^^^^^^
  File "/home/airflow/.local/lib/python3.12/site-packages/airflow/utils/operator_helpers.py", line 252, in run
    return self.func(*args, **kwargs)
           ^^^^^^^^^^^^^^^^^^^^^^^^^^
  File "/opt/airflow/dags/beer_data_processing_dag.py", line 260, in create_fact_table
    cursor.execute(query, values)
psycopg2.errors.UndefinedColumn: column "review_aroma" of relation "fact_beer" does not exist
LINE 2: ...sweet, sour, salty, fruits, hoppy, spices, malty, review_aro...
                                                             ^

[2025-04-10T07:13:20.605+0000] {local_task_job_runner.py:266} INFO - Task exited with return code 1
[2025-04-10T07:13:20.666+0000] {taskinstance.py:3901} INFO - 0 downstream tasks scheduled from follow-on schedule check
[2025-04-10T07:13:20.671+0000] {local_task_job_runner.py:245} INFO - ::endgroup::
