[2025-04-16T15:26:23.338+0000] {local_task_job_runner.py:123} INFO - ::group::Pre task execution logs
[2025-04-16T15:26:24.014+0000] {taskinstance.py:2614} INFO - Dependencies all met for dep_context=non-requeueable deps ti=<TaskInstance: beer_data_processing.create_fact_beer_table scheduled__2025-04-16T13:00:00+00:00 [queued]>
[2025-04-16T15:26:24.284+0000] {taskinstance.py:2614} INFO - Dependencies all met for dep_context=requeueable deps ti=<TaskInstance: beer_data_processing.create_fact_beer_table scheduled__2025-04-16T13:00:00+00:00 [queued]>
[2025-04-16T15:26:24.300+0000] {taskinstance.py:2867} INFO - Starting attempt 2 of 6
[2025-04-16T15:26:24.768+0000] {taskinstance.py:2890} INFO - Executing <Task(SQLExecuteQueryOperator): create_fact_beer_table> on 2025-04-16 13:00:00+00:00
[2025-04-16T15:26:26.392+0000] {logging_mixin.py:190} WARNING - /home/***/.local/lib/python3.12/site-packages/***/task/task_runner/standard_task_runner.py:70 DeprecationWarning: This process (pid=55024) is multi-threaded, use of fork() may lead to deadlocks in the child.
[2025-04-16T15:26:26.605+0000] {standard_task_runner.py:72} INFO - Started process 55214 to run task
[2025-04-16T15:26:26.524+0000] {standard_task_runner.py:104} INFO - Running: ['***', 'tasks', 'run', 'beer_data_processing', 'create_fact_beer_table', 'scheduled__2025-04-16T13:00:00+00:00', '--job-id', '599', '--raw', '--subdir', 'DAGS_FOLDER/beer_data_processing_dag.py', '--cfg-path', '/tmp/tmplxnfhowc']
[2025-04-16T15:26:26.699+0000] {standard_task_runner.py:105} INFO - Job 599: Subtask create_fact_beer_table
[2025-04-16T15:26:29.646+0000] {task_command.py:467} INFO - Running <TaskInstance: beer_data_processing.create_fact_beer_table scheduled__2025-04-16T13:00:00+00:00 [running]> on host 3e53738720c8
[2025-04-16T15:26:30.999+0000] {taskinstance.py:3134} INFO - Exporting env vars: AIRFLOW_CTX_DAG_OWNER='***' AIRFLOW_CTX_DAG_ID='beer_data_processing' AIRFLOW_CTX_TASK_ID='create_fact_beer_table' AIRFLOW_CTX_EXECUTION_DATE='2025-04-16T13:00:00+00:00' AIRFLOW_CTX_TRY_NUMBER='2' AIRFLOW_CTX_DAG_RUN_ID='scheduled__2025-04-16T13:00:00+00:00'
[2025-04-16T15:26:31.124+0000] {logging_mixin.py:190} INFO - Task instance is in running state
[2025-04-16T15:26:31.161+0000] {logging_mixin.py:190} INFO -  Previous state of the Task instance: queued
[2025-04-16T15:26:31.170+0000] {logging_mixin.py:190} INFO - Current task name:create_fact_beer_table state:running start_date:2025-04-16 15:26:24.074645+00:00
[2025-04-16T15:26:31.255+0000] {logging_mixin.py:190} INFO - Dag name:beer_data_processing and current dag run status:running
[2025-04-16T15:26:31.336+0000] {taskinstance.py:732} INFO - ::endgroup::
[2025-04-16T15:26:31.371+0000] {sql.py:295} INFO - Executing: 
    CREATE TABLE IF NOT EXISTS fact_beer (
        beer_id INTEGER REFERENCES dim_beer(beer_id),
        style_id INTEGER REFERENCES dim_style(style_id),
        brewery_id INTEGER REFERENCES dim_brewery(brewery_id),
        abv FLOAT,
        min_ibu FLOAT,
        max_ibu FLOAT,
        astringency FLOAT,
        body FLOAT,
        alcohol FLOAT,
        bitter FLOAT,
        sweet FLOAT,
        sour FLOAT,
        salty FLOAT,
        fruits FLOAT,
        hoppy FLOAT,
        spices FLOAT,
        malty FLOAT,
        review_aroma NUMERIC(3,2),
        review_appearance NUMERIC(3,2),
        review_palate NUMERIC(3,2),
        review_taste NUMERIC(3,2),
        average_review_overall NUMERIC(3,2),
        number_of_reviews INTEGER DEFAULT 1,
        is_active BOOLEAN DEFAULT TRUE,
        last_updated TIMESTAMP DEFAULT CURRENT_TIMESTAMP,
        PRIMARY KEY (beer_id, style_id, brewery_id)
    );
    
[2025-04-16T15:26:31.518+0000] {base.py:84} INFO - Retrieving connection 'postgres_conn'
[2025-04-16T15:26:31.721+0000] {base.py:84} INFO - Retrieving connection 'postgres_conn'
[2025-04-16T15:26:31.812+0000] {sql.py:511} INFO - Running statement: 
    CREATE TABLE IF NOT EXISTS fact_beer (
        beer_id INTEGER REFERENCES dim_beer(beer_id),
        style_id INTEGER REFERENCES dim_style(style_id),
        brewery_id INTEGER REFERENCES dim_brewery(brewery_id),
        abv FLOAT,
        min_ibu FLOAT,
        max_ibu FLOAT,
        astringency FLOAT,
        body FLOAT,
        alcohol FLOAT,
        bitter FLOAT,
        sweet FLOAT,
        sour FLOAT,
        salty FLOAT,
        fruits FLOAT,
        hoppy FLOAT,
        spices FLOAT,
        malty FLOAT,
        review_aroma NUMERIC(3,2),
        review_appearance NUMERIC(3,2),
        review_palate NUMERIC(3,2),
        review_taste NUMERIC(3,2),
        average_review_overall NUMERIC(3,2),
        number_of_reviews INTEGER DEFAULT 1,
        is_active BOOLEAN DEFAULT TRUE,
        last_updated TIMESTAMP DEFAULT CURRENT_TIMESTAMP,
        PRIMARY KEY (beer_id, style_id, brewery_id)
    );
    , parameters: None
[2025-04-16T15:26:31.948+0000] {logging_mixin.py:190} WARNING - /home/***/.local/lib/python3.12/site-packages/***/providers/common/sql/hooks/sql.py:470 DeprecationWarning: Import of fetch_all_handler from the '***.providers.common.sql.hooks' module is deprecated and will
be removed in the future. Please import it from '***.providers.common.sql.hooks.handlers'.
[2025-04-16T15:26:32.058+0000] {logging_mixin.py:190} WARNING - /home/***/.local/lib/python3.12/site-packages/***/providers/common/sql/hooks/sql.py:471 DeprecationWarning: Import of return_single_query_results from the '***.providers.common.sql.hooks' module is deprecated and will
be removed in the future. Please import it from '***.providers.common.sql.hooks.handlers'.
[2025-04-16T15:26:32.087+0000] {logging_mixin.py:190} WARNING - /home/***/.local/lib/python3.12/site-packages/***/providers/common/sql/hooks/sql.py:486 DeprecationWarning: Import of return_single_query_results from the '***.providers.common.sql.hooks' module is deprecated and will
be removed in the future. Please import it from '***.providers.common.sql.hooks.handlers'.
[2025-04-16T15:26:32.102+0000] {logging_mixin.py:190} WARNING - /home/***/.local/lib/python3.12/site-packages/***/providers/common/sql/operators/sql.py:311 DeprecationWarning: Import of return_single_query_results from the '***.providers.common.sql.hooks' module is deprecated and will
be removed in the future. Please import it from '***.providers.common.sql.hooks.handlers'.
[2025-04-16T15:27:41.265+0000] {taskinstance.py:3313} ERROR - Task failed with exception
Traceback (most recent call last):
  File "/home/airflow/.local/lib/python3.12/site-packages/sqlalchemy/engine/base.py", line 3371, in _wrap_pool_connect
    return fn()
           ^^^^
  File "/home/airflow/.local/lib/python3.12/site-packages/sqlalchemy/pool/base.py", line 327, in connect
    return _ConnectionFairy._checkout(self)
           ^^^^^^^^^^^^^^^^^^^^^^^^^^^^^^^^
  File "/home/airflow/.local/lib/python3.12/site-packages/sqlalchemy/pool/base.py", line 894, in _checkout
    fairy = _ConnectionRecord.checkout(pool)
            ^^^^^^^^^^^^^^^^^^^^^^^^^^^^^^^^
  File "/home/airflow/.local/lib/python3.12/site-packages/sqlalchemy/pool/base.py", line 493, in checkout
    rec = pool._do_get()
          ^^^^^^^^^^^^^^
  File "/home/airflow/.local/lib/python3.12/site-packages/sqlalchemy/pool/impl.py", line 256, in _do_get
    return self._create_connection()
           ^^^^^^^^^^^^^^^^^^^^^^^^^
  File "/home/airflow/.local/lib/python3.12/site-packages/sqlalchemy/pool/base.py", line 273, in _create_connection
    return _ConnectionRecord(self)
           ^^^^^^^^^^^^^^^^^^^^^^^
  File "/home/airflow/.local/lib/python3.12/site-packages/sqlalchemy/pool/base.py", line 388, in __init__
    self.__connect()
  File "/home/airflow/.local/lib/python3.12/site-packages/sqlalchemy/pool/base.py", line 690, in __connect
    with util.safe_reraise():
         ^^^^^^^^^^^^^^^^^^^
  File "/home/airflow/.local/lib/python3.12/site-packages/sqlalchemy/util/langhelpers.py", line 70, in __exit__
    compat.raise_(
  File "/home/airflow/.local/lib/python3.12/site-packages/sqlalchemy/util/compat.py", line 211, in raise_
    raise exception
  File "/home/airflow/.local/lib/python3.12/site-packages/sqlalchemy/pool/base.py", line 686, in __connect
    self.dbapi_connection = connection = pool._invoke_creator(self)
                                         ^^^^^^^^^^^^^^^^^^^^^^^^^^
  File "/home/airflow/.local/lib/python3.12/site-packages/sqlalchemy/engine/create.py", line 574, in connect
    return dialect.connect(*cargs, **cparams)
           ^^^^^^^^^^^^^^^^^^^^^^^^^^^^^^^^^^
  File "/home/airflow/.local/lib/python3.12/site-packages/sqlalchemy/engine/default.py", line 598, in connect
    return self.dbapi.connect(*cargs, **cparams)
           ^^^^^^^^^^^^^^^^^^^^^^^^^^^^^^^^^^^^^
  File "/home/airflow/.local/lib/python3.12/site-packages/psycopg2/__init__.py", line 122, in connect
    conn = _connect(dsn, connection_factory=connection_factory, **kwasync)
           ^^^^^^^^^^^^^^^^^^^^^^^^^^^^^^^^^^^^^^^^^^^^^^^^^^^^^^^^^^^^^^^
psycopg2.OperationalError: could not translate host name "postgres" to address: Temporary failure in name resolution


The above exception was the direct cause of the following exception:

Traceback (most recent call last):
  File "/home/airflow/.local/lib/python3.12/site-packages/airflow/models/taskinstance.py", line 281, in _run_raw_task
    ti.refresh_from_db(lock_for_update=True, session=session)
  File "/home/airflow/.local/lib/python3.12/site-packages/airflow/utils/session.py", line 94, in wrapper
    return func(*args, **kwargs)
           ^^^^^^^^^^^^^^^^^^^^^
  File "/home/airflow/.local/lib/python3.12/site-packages/airflow/models/taskinstance.py", line 2360, in refresh_from_db
    _refresh_from_db(task_instance=self, session=session, lock_for_update=lock_for_update)
  File "/home/airflow/.local/lib/python3.12/site-packages/airflow/models/taskinstance.py", line 873, in _refresh_from_db
    ti = TaskInstance.get_task_instance(
         ^^^^^^^^^^^^^^^^^^^^^^^^^^^^^^^
  File "/home/airflow/.local/lib/python3.12/site-packages/airflow/api_internal/internal_api_call.py", line 166, in wrapper
    return func(*args, **kwargs)
           ^^^^^^^^^^^^^^^^^^^^^
  File "/home/airflow/.local/lib/python3.12/site-packages/airflow/utils/session.py", line 94, in wrapper
    return func(*args, **kwargs)
           ^^^^^^^^^^^^^^^^^^^^^
  File "/home/airflow/.local/lib/python3.12/site-packages/airflow/models/taskinstance.py", line 2342, in get_task_instance
    for attempt in run_with_db_retries(logger=cls.logger()):
                   ^^^^^^^^^^^^^^^^^^^^^^^^^^^^^^^^^^^^^^^^
  File "/home/airflow/.local/lib/python3.12/site-packages/tenacity/__init__.py", line 443, in __iter__
    do = self.iter(retry_state=retry_state)
         ^^^^^^^^^^^^^^^^^^^^^^^^^^^^^^^^^^
  File "/home/airflow/.local/lib/python3.12/site-packages/tenacity/__init__.py", line 376, in iter
    result = action(retry_state)
             ^^^^^^^^^^^^^^^^^^^
  File "/home/airflow/.local/lib/python3.12/site-packages/tenacity/__init__.py", line 418, in exc_check
    raise retry_exc.reraise()
          ^^^^^^^^^^^^^^^^^^^
  File "/home/airflow/.local/lib/python3.12/site-packages/tenacity/__init__.py", line 185, in reraise
    raise self.last_attempt.result()
          ^^^^^^^^^^^^^^^^^^^^^^^^^^
  File "/usr/local/lib/python3.12/concurrent/futures/_base.py", line 449, in result
    return self.__get_result()
           ^^^^^^^^^^^^^^^^^^^
  File "/usr/local/lib/python3.12/concurrent/futures/_base.py", line 401, in __get_result
    raise self._exception
  File "/home/airflow/.local/lib/python3.12/site-packages/airflow/models/taskinstance.py", line 2344, in get_task_instance
    return query.with_for_update().one_or_none()
           ^^^^^^^^^^^^^^^^^^^^^^^^^^^^^^^^^^^^^
  File "/home/airflow/.local/lib/python3.12/site-packages/sqlalchemy/orm/query.py", line 2850, in one_or_none
    return self._iter().one_or_none()
           ^^^^^^^^^^^^
  File "/home/airflow/.local/lib/python3.12/site-packages/sqlalchemy/orm/query.py", line 2916, in _iter
    result = self.session.execute(
             ^^^^^^^^^^^^^^^^^^^^^
  File "/home/airflow/.local/lib/python3.12/site-packages/sqlalchemy/orm/session.py", line 1716, in execute
    conn = self._connection_for_bind(bind)
           ^^^^^^^^^^^^^^^^^^^^^^^^^^^^^^^
  File "/home/airflow/.local/lib/python3.12/site-packages/sqlalchemy/orm/session.py", line 1555, in _connection_for_bind
    return self._transaction._connection_for_bind(
           ^^^^^^^^^^^^^^^^^^^^^^^^^^^^^^^^^^^^^^^
  File "/home/airflow/.local/lib/python3.12/site-packages/sqlalchemy/orm/session.py", line 750, in _connection_for_bind
    conn = bind.connect()
           ^^^^^^^^^^^^^^
  File "/home/airflow/.local/lib/python3.12/site-packages/sqlalchemy/future/engine.py", line 412, in connect
    return super(Engine, self).connect()
           ^^^^^^^^^^^^^^^^^^^^^^^^^^^^^
  File "/home/airflow/.local/lib/python3.12/site-packages/sqlalchemy/engine/base.py", line 3325, in connect
    return self._connection_cls(self, close_with_result=close_with_result)
           ^^^^^^^^^^^^^^^^^^^^^^^^^^^^^^^^^^^^^^^^^^^^^^^^^^^^^^^^^^^^^^^
  File "/home/airflow/.local/lib/python3.12/site-packages/sqlalchemy/engine/base.py", line 96, in __init__
    else engine.raw_connection()
         ^^^^^^^^^^^^^^^^^^^^^^^
  File "/home/airflow/.local/lib/python3.12/site-packages/sqlalchemy/engine/base.py", line 3404, in raw_connection
    return self._wrap_pool_connect(self.pool.connect, _connection)
           ^^^^^^^^^^^^^^^^^^^^^^^^^^^^^^^^^^^^^^^^^^^^^^^^^^^^^^^
  File "/home/airflow/.local/lib/python3.12/site-packages/sqlalchemy/engine/base.py", line 3374, in _wrap_pool_connect
    Connection._handle_dbapi_exception_noconnection(
  File "/home/airflow/.local/lib/python3.12/site-packages/sqlalchemy/engine/base.py", line 2208, in _handle_dbapi_exception_noconnection
    util.raise_(
  File "/home/airflow/.local/lib/python3.12/site-packages/sqlalchemy/util/compat.py", line 211, in raise_
    raise exception
  File "/home/airflow/.local/lib/python3.12/site-packages/sqlalchemy/engine/base.py", line 3371, in _wrap_pool_connect
    return fn()
           ^^^^
  File "/home/airflow/.local/lib/python3.12/site-packages/sqlalchemy/pool/base.py", line 327, in connect
    return _ConnectionFairy._checkout(self)
           ^^^^^^^^^^^^^^^^^^^^^^^^^^^^^^^^
  File "/home/airflow/.local/lib/python3.12/site-packages/sqlalchemy/pool/base.py", line 894, in _checkout
    fairy = _ConnectionRecord.checkout(pool)
            ^^^^^^^^^^^^^^^^^^^^^^^^^^^^^^^^
  File "/home/airflow/.local/lib/python3.12/site-packages/sqlalchemy/pool/base.py", line 493, in checkout
    rec = pool._do_get()
          ^^^^^^^^^^^^^^
  File "/home/airflow/.local/lib/python3.12/site-packages/sqlalchemy/pool/impl.py", line 256, in _do_get
    return self._create_connection()
           ^^^^^^^^^^^^^^^^^^^^^^^^^
  File "/home/airflow/.local/lib/python3.12/site-packages/sqlalchemy/pool/base.py", line 273, in _create_connection
    return _ConnectionRecord(self)
           ^^^^^^^^^^^^^^^^^^^^^^^
  File "/home/airflow/.local/lib/python3.12/site-packages/sqlalchemy/pool/base.py", line 388, in __init__
    self.__connect()
  File "/home/airflow/.local/lib/python3.12/site-packages/sqlalchemy/pool/base.py", line 690, in __connect
    with util.safe_reraise():
         ^^^^^^^^^^^^^^^^^^^
  File "/home/airflow/.local/lib/python3.12/site-packages/sqlalchemy/util/langhelpers.py", line 70, in __exit__
    compat.raise_(
  File "/home/airflow/.local/lib/python3.12/site-packages/sqlalchemy/util/compat.py", line 211, in raise_
    raise exception
  File "/home/airflow/.local/lib/python3.12/site-packages/sqlalchemy/pool/base.py", line 686, in __connect
    self.dbapi_connection = connection = pool._invoke_creator(self)
                                         ^^^^^^^^^^^^^^^^^^^^^^^^^^
  File "/home/airflow/.local/lib/python3.12/site-packages/sqlalchemy/engine/create.py", line 574, in connect
    return dialect.connect(*cargs, **cparams)
           ^^^^^^^^^^^^^^^^^^^^^^^^^^^^^^^^^^
  File "/home/airflow/.local/lib/python3.12/site-packages/sqlalchemy/engine/default.py", line 598, in connect
    return self.dbapi.connect(*cargs, **cparams)
           ^^^^^^^^^^^^^^^^^^^^^^^^^^^^^^^^^^^^^
  File "/home/airflow/.local/lib/python3.12/site-packages/psycopg2/__init__.py", line 122, in connect
    conn = _connect(dsn, connection_factory=connection_factory, **kwasync)
           ^^^^^^^^^^^^^^^^^^^^^^^^^^^^^^^^^^^^^^^^^^^^^^^^^^^^^^^^^^^^^^^
sqlalchemy.exc.OperationalError: (psycopg2.OperationalError) could not translate host name "postgres" to address: Temporary failure in name resolution

(Background on this error at: https://sqlalche.me/e/14/e3q8)
[2025-04-16T15:27:51.595+0000] {taskinstance.py:341} INFO - ::group::Post task execution logs
[2025-04-16T15:27:52.293+0000] {standard_task_runner.py:124} ERROR - Failed to execute job 599 for task create_fact_beer_table ((psycopg2.OperationalError) could not translate host name "postgres" to address: Temporary failure in name resolution

(Background on this error at: https://sqlalche.me/e/14/e3q8); 55214)
Traceback (most recent call last):
  File "/home/airflow/.local/lib/python3.12/site-packages/sqlalchemy/engine/base.py", line 3371, in _wrap_pool_connect
    return fn()
           ^^^^
  File "/home/airflow/.local/lib/python3.12/site-packages/sqlalchemy/pool/base.py", line 327, in connect
    return _ConnectionFairy._checkout(self)
           ^^^^^^^^^^^^^^^^^^^^^^^^^^^^^^^^
  File "/home/airflow/.local/lib/python3.12/site-packages/sqlalchemy/pool/base.py", line 894, in _checkout
    fairy = _ConnectionRecord.checkout(pool)
            ^^^^^^^^^^^^^^^^^^^^^^^^^^^^^^^^
  File "/home/airflow/.local/lib/python3.12/site-packages/sqlalchemy/pool/base.py", line 493, in checkout
    rec = pool._do_get()
          ^^^^^^^^^^^^^^
  File "/home/airflow/.local/lib/python3.12/site-packages/sqlalchemy/pool/impl.py", line 256, in _do_get
    return self._create_connection()
           ^^^^^^^^^^^^^^^^^^^^^^^^^
  File "/home/airflow/.local/lib/python3.12/site-packages/sqlalchemy/pool/base.py", line 273, in _create_connection
    return _ConnectionRecord(self)
           ^^^^^^^^^^^^^^^^^^^^^^^
  File "/home/airflow/.local/lib/python3.12/site-packages/sqlalchemy/pool/base.py", line 388, in __init__
    self.__connect()
  File "/home/airflow/.local/lib/python3.12/site-packages/sqlalchemy/pool/base.py", line 690, in __connect
    with util.safe_reraise():
         ^^^^^^^^^^^^^^^^^^^
  File "/home/airflow/.local/lib/python3.12/site-packages/sqlalchemy/util/langhelpers.py", line 70, in __exit__
    compat.raise_(
  File "/home/airflow/.local/lib/python3.12/site-packages/sqlalchemy/util/compat.py", line 211, in raise_
    raise exception
  File "/home/airflow/.local/lib/python3.12/site-packages/sqlalchemy/pool/base.py", line 686, in __connect
    self.dbapi_connection = connection = pool._invoke_creator(self)
                                         ^^^^^^^^^^^^^^^^^^^^^^^^^^
  File "/home/airflow/.local/lib/python3.12/site-packages/sqlalchemy/engine/create.py", line 574, in connect
    return dialect.connect(*cargs, **cparams)
           ^^^^^^^^^^^^^^^^^^^^^^^^^^^^^^^^^^
  File "/home/airflow/.local/lib/python3.12/site-packages/sqlalchemy/engine/default.py", line 598, in connect
    return self.dbapi.connect(*cargs, **cparams)
           ^^^^^^^^^^^^^^^^^^^^^^^^^^^^^^^^^^^^^
  File "/home/airflow/.local/lib/python3.12/site-packages/psycopg2/__init__.py", line 122, in connect
    conn = _connect(dsn, connection_factory=connection_factory, **kwasync)
           ^^^^^^^^^^^^^^^^^^^^^^^^^^^^^^^^^^^^^^^^^^^^^^^^^^^^^^^^^^^^^^^
psycopg2.OperationalError: could not translate host name "postgres" to address: Temporary failure in name resolution


The above exception was the direct cause of the following exception:

Traceback (most recent call last):
  File "/home/airflow/.local/lib/python3.12/site-packages/airflow/models/taskinstance.py", line 281, in _run_raw_task
    ti.refresh_from_db(lock_for_update=True, session=session)
  File "/home/airflow/.local/lib/python3.12/site-packages/airflow/utils/session.py", line 94, in wrapper
    return func(*args, **kwargs)
           ^^^^^^^^^^^^^^^^^^^^^
  File "/home/airflow/.local/lib/python3.12/site-packages/airflow/models/taskinstance.py", line 2360, in refresh_from_db
    _refresh_from_db(task_instance=self, session=session, lock_for_update=lock_for_update)
  File "/home/airflow/.local/lib/python3.12/site-packages/airflow/models/taskinstance.py", line 873, in _refresh_from_db
    ti = TaskInstance.get_task_instance(
         ^^^^^^^^^^^^^^^^^^^^^^^^^^^^^^^
  File "/home/airflow/.local/lib/python3.12/site-packages/airflow/api_internal/internal_api_call.py", line 166, in wrapper
    return func(*args, **kwargs)
           ^^^^^^^^^^^^^^^^^^^^^
  File "/home/airflow/.local/lib/python3.12/site-packages/airflow/utils/session.py", line 94, in wrapper
    return func(*args, **kwargs)
           ^^^^^^^^^^^^^^^^^^^^^
  File "/home/airflow/.local/lib/python3.12/site-packages/airflow/models/taskinstance.py", line 2342, in get_task_instance
    for attempt in run_with_db_retries(logger=cls.logger()):
                   ^^^^^^^^^^^^^^^^^^^^^^^^^^^^^^^^^^^^^^^^
  File "/home/airflow/.local/lib/python3.12/site-packages/tenacity/__init__.py", line 443, in __iter__
    do = self.iter(retry_state=retry_state)
         ^^^^^^^^^^^^^^^^^^^^^^^^^^^^^^^^^^
  File "/home/airflow/.local/lib/python3.12/site-packages/tenacity/__init__.py", line 376, in iter
    result = action(retry_state)
             ^^^^^^^^^^^^^^^^^^^
  File "/home/airflow/.local/lib/python3.12/site-packages/tenacity/__init__.py", line 418, in exc_check
    raise retry_exc.reraise()
          ^^^^^^^^^^^^^^^^^^^
  File "/home/airflow/.local/lib/python3.12/site-packages/tenacity/__init__.py", line 185, in reraise
    raise self.last_attempt.result()
          ^^^^^^^^^^^^^^^^^^^^^^^^^^
  File "/usr/local/lib/python3.12/concurrent/futures/_base.py", line 449, in result
    return self.__get_result()
           ^^^^^^^^^^^^^^^^^^^
  File "/usr/local/lib/python3.12/concurrent/futures/_base.py", line 401, in __get_result
    raise self._exception
  File "/home/airflow/.local/lib/python3.12/site-packages/airflow/models/taskinstance.py", line 2344, in get_task_instance
    return query.with_for_update().one_or_none()
           ^^^^^^^^^^^^^^^^^^^^^^^^^^^^^^^^^^^^^
  File "/home/airflow/.local/lib/python3.12/site-packages/sqlalchemy/orm/query.py", line 2850, in one_or_none
    return self._iter().one_or_none()
           ^^^^^^^^^^^^
  File "/home/airflow/.local/lib/python3.12/site-packages/sqlalchemy/orm/query.py", line 2916, in _iter
    result = self.session.execute(
             ^^^^^^^^^^^^^^^^^^^^^
  File "/home/airflow/.local/lib/python3.12/site-packages/sqlalchemy/orm/session.py", line 1716, in execute
    conn = self._connection_for_bind(bind)
           ^^^^^^^^^^^^^^^^^^^^^^^^^^^^^^^
  File "/home/airflow/.local/lib/python3.12/site-packages/sqlalchemy/orm/session.py", line 1555, in _connection_for_bind
    return self._transaction._connection_for_bind(
           ^^^^^^^^^^^^^^^^^^^^^^^^^^^^^^^^^^^^^^^
  File "/home/airflow/.local/lib/python3.12/site-packages/sqlalchemy/orm/session.py", line 750, in _connection_for_bind
    conn = bind.connect()
           ^^^^^^^^^^^^^^
  File "/home/airflow/.local/lib/python3.12/site-packages/sqlalchemy/future/engine.py", line 412, in connect
    return super(Engine, self).connect()
           ^^^^^^^^^^^^^^^^^^^^^^^^^^^^^
  File "/home/airflow/.local/lib/python3.12/site-packages/sqlalchemy/engine/base.py", line 3325, in connect
    return self._connection_cls(self, close_with_result=close_with_result)
           ^^^^^^^^^^^^^^^^^^^^^^^^^^^^^^^^^^^^^^^^^^^^^^^^^^^^^^^^^^^^^^^
  File "/home/airflow/.local/lib/python3.12/site-packages/sqlalchemy/engine/base.py", line 96, in __init__
    else engine.raw_connection()
         ^^^^^^^^^^^^^^^^^^^^^^^
  File "/home/airflow/.local/lib/python3.12/site-packages/sqlalchemy/engine/base.py", line 3404, in raw_connection
    return self._wrap_pool_connect(self.pool.connect, _connection)
           ^^^^^^^^^^^^^^^^^^^^^^^^^^^^^^^^^^^^^^^^^^^^^^^^^^^^^^^
  File "/home/airflow/.local/lib/python3.12/site-packages/sqlalchemy/engine/base.py", line 3374, in _wrap_pool_connect
    Connection._handle_dbapi_exception_noconnection(
  File "/home/airflow/.local/lib/python3.12/site-packages/sqlalchemy/engine/base.py", line 2208, in _handle_dbapi_exception_noconnection
    util.raise_(
  File "/home/airflow/.local/lib/python3.12/site-packages/sqlalchemy/util/compat.py", line 211, in raise_
    raise exception
  File "/home/airflow/.local/lib/python3.12/site-packages/sqlalchemy/engine/base.py", line 3371, in _wrap_pool_connect
    return fn()
           ^^^^
  File "/home/airflow/.local/lib/python3.12/site-packages/sqlalchemy/pool/base.py", line 327, in connect
    return _ConnectionFairy._checkout(self)
           ^^^^^^^^^^^^^^^^^^^^^^^^^^^^^^^^
  File "/home/airflow/.local/lib/python3.12/site-packages/sqlalchemy/pool/base.py", line 894, in _checkout
    fairy = _ConnectionRecord.checkout(pool)
            ^^^^^^^^^^^^^^^^^^^^^^^^^^^^^^^^
  File "/home/airflow/.local/lib/python3.12/site-packages/sqlalchemy/pool/base.py", line 493, in checkout
    rec = pool._do_get()
          ^^^^^^^^^^^^^^
  File "/home/airflow/.local/lib/python3.12/site-packages/sqlalchemy/pool/impl.py", line 256, in _do_get
    return self._create_connection()
           ^^^^^^^^^^^^^^^^^^^^^^^^^
  File "/home/airflow/.local/lib/python3.12/site-packages/sqlalchemy/pool/base.py", line 273, in _create_connection
    return _ConnectionRecord(self)
           ^^^^^^^^^^^^^^^^^^^^^^^
  File "/home/airflow/.local/lib/python3.12/site-packages/sqlalchemy/pool/base.py", line 388, in __init__
    self.__connect()
  File "/home/airflow/.local/lib/python3.12/site-packages/sqlalchemy/pool/base.py", line 690, in __connect
    with util.safe_reraise():
         ^^^^^^^^^^^^^^^^^^^
  File "/home/airflow/.local/lib/python3.12/site-packages/sqlalchemy/util/langhelpers.py", line 70, in __exit__
    compat.raise_(
  File "/home/airflow/.local/lib/python3.12/site-packages/sqlalchemy/util/compat.py", line 211, in raise_
    raise exception
  File "/home/airflow/.local/lib/python3.12/site-packages/sqlalchemy/pool/base.py", line 686, in __connect
    self.dbapi_connection = connection = pool._invoke_creator(self)
                                         ^^^^^^^^^^^^^^^^^^^^^^^^^^
  File "/home/airflow/.local/lib/python3.12/site-packages/sqlalchemy/engine/create.py", line 574, in connect
    return dialect.connect(*cargs, **cparams)
           ^^^^^^^^^^^^^^^^^^^^^^^^^^^^^^^^^^
  File "/home/airflow/.local/lib/python3.12/site-packages/sqlalchemy/engine/default.py", line 598, in connect
    return self.dbapi.connect(*cargs, **cparams)
           ^^^^^^^^^^^^^^^^^^^^^^^^^^^^^^^^^^^^^
  File "/home/airflow/.local/lib/python3.12/site-packages/psycopg2/__init__.py", line 122, in connect
    conn = _connect(dsn, connection_factory=connection_factory, **kwasync)
           ^^^^^^^^^^^^^^^^^^^^^^^^^^^^^^^^^^^^^^^^^^^^^^^^^^^^^^^^^^^^^^^
sqlalchemy.exc.OperationalError: (psycopg2.OperationalError) could not translate host name "postgres" to address: Temporary failure in name resolution

(Background on this error at: https://sqlalche.me/e/14/e3q8)

During handling of the above exception, another exception occurred:

Traceback (most recent call last):
  File "/home/airflow/.local/lib/python3.12/site-packages/sqlalchemy/engine/base.py", line 3371, in _wrap_pool_connect
    return fn()
           ^^^^
  File "/home/airflow/.local/lib/python3.12/site-packages/sqlalchemy/pool/base.py", line 327, in connect
    return _ConnectionFairy._checkout(self)
           ^^^^^^^^^^^^^^^^^^^^^^^^^^^^^^^^
  File "/home/airflow/.local/lib/python3.12/site-packages/sqlalchemy/pool/base.py", line 894, in _checkout
    fairy = _ConnectionRecord.checkout(pool)
            ^^^^^^^^^^^^^^^^^^^^^^^^^^^^^^^^
  File "/home/airflow/.local/lib/python3.12/site-packages/sqlalchemy/pool/base.py", line 493, in checkout
    rec = pool._do_get()
          ^^^^^^^^^^^^^^
  File "/home/airflow/.local/lib/python3.12/site-packages/sqlalchemy/pool/impl.py", line 256, in _do_get
    return self._create_connection()
           ^^^^^^^^^^^^^^^^^^^^^^^^^
  File "/home/airflow/.local/lib/python3.12/site-packages/sqlalchemy/pool/base.py", line 273, in _create_connection
    return _ConnectionRecord(self)
           ^^^^^^^^^^^^^^^^^^^^^^^
  File "/home/airflow/.local/lib/python3.12/site-packages/sqlalchemy/pool/base.py", line 388, in __init__
    self.__connect()
  File "/home/airflow/.local/lib/python3.12/site-packages/sqlalchemy/pool/base.py", line 690, in __connect
    with util.safe_reraise():
         ^^^^^^^^^^^^^^^^^^^
  File "/home/airflow/.local/lib/python3.12/site-packages/sqlalchemy/util/langhelpers.py", line 70, in __exit__
    compat.raise_(
  File "/home/airflow/.local/lib/python3.12/site-packages/sqlalchemy/util/compat.py", line 211, in raise_
    raise exception
  File "/home/airflow/.local/lib/python3.12/site-packages/sqlalchemy/pool/base.py", line 686, in __connect
    self.dbapi_connection = connection = pool._invoke_creator(self)
                                         ^^^^^^^^^^^^^^^^^^^^^^^^^^
  File "/home/airflow/.local/lib/python3.12/site-packages/sqlalchemy/engine/create.py", line 574, in connect
    return dialect.connect(*cargs, **cparams)
           ^^^^^^^^^^^^^^^^^^^^^^^^^^^^^^^^^^
  File "/home/airflow/.local/lib/python3.12/site-packages/sqlalchemy/engine/default.py", line 598, in connect
    return self.dbapi.connect(*cargs, **cparams)
           ^^^^^^^^^^^^^^^^^^^^^^^^^^^^^^^^^^^^^
  File "/home/airflow/.local/lib/python3.12/site-packages/psycopg2/__init__.py", line 122, in connect
    conn = _connect(dsn, connection_factory=connection_factory, **kwasync)
           ^^^^^^^^^^^^^^^^^^^^^^^^^^^^^^^^^^^^^^^^^^^^^^^^^^^^^^^^^^^^^^^
psycopg2.OperationalError: could not translate host name "postgres" to address: Temporary failure in name resolution


The above exception was the direct cause of the following exception:

Traceback (most recent call last):
  File "/home/airflow/.local/lib/python3.12/site-packages/airflow/task/task_runner/standard_task_runner.py", line 117, in _start_by_fork
    ret = args.func(args, dag=self.dag)
          ^^^^^^^^^^^^^^^^^^^^^^^^^^^^^
  File "/home/airflow/.local/lib/python3.12/site-packages/airflow/cli/cli_config.py", line 49, in command
    return func(*args, **kwargs)
           ^^^^^^^^^^^^^^^^^^^^^
  File "/home/airflow/.local/lib/python3.12/site-packages/airflow/utils/cli.py", line 116, in wrapper
    return f(*args, **kwargs)
           ^^^^^^^^^^^^^^^^^^
  File "/home/airflow/.local/lib/python3.12/site-packages/airflow/cli/commands/task_command.py", line 483, in task_run
    task_return_code = _run_task_by_selected_method(args, _dag, ti)
                       ^^^^^^^^^^^^^^^^^^^^^^^^^^^^^^^^^^^^^^^^^^^^
  File "/home/airflow/.local/lib/python3.12/site-packages/airflow/cli/commands/task_command.py", line 256, in _run_task_by_selected_method
    return _run_raw_task(args, ti)
           ^^^^^^^^^^^^^^^^^^^^^^^
  File "/home/airflow/.local/lib/python3.12/site-packages/airflow/cli/commands/task_command.py", line 341, in _run_raw_task
    return ti._run_raw_task(
           ^^^^^^^^^^^^^^^^^
  File "/home/airflow/.local/lib/python3.12/site-packages/airflow/utils/session.py", line 97, in wrapper
    return func(*args, session=session, **kwargs)
           ^^^^^^^^^^^^^^^^^^^^^^^^^^^^^^^^^^^^^^
  File "/home/airflow/.local/lib/python3.12/site-packages/airflow/models/taskinstance.py", line 3006, in _run_raw_task
    return _run_raw_task(
           ^^^^^^^^^^^^^^
  File "/home/airflow/.local/lib/python3.12/site-packages/airflow/models/taskinstance.py", line 337, in _run_raw_task
    ti.handle_failure(e, test_mode, context, session=session)
  File "/home/airflow/.local/lib/python3.12/site-packages/airflow/utils/session.py", line 94, in wrapper
    return func(*args, **kwargs)
           ^^^^^^^^^^^^^^^^^^^^^
  File "/home/airflow/.local/lib/python3.12/site-packages/airflow/models/taskinstance.py", line 3434, in handle_failure
    _handle_failure(
  File "/home/airflow/.local/lib/python3.12/site-packages/airflow/utils/session.py", line 94, in wrapper
    return func(*args, **kwargs)
           ^^^^^^^^^^^^^^^^^^^^^
  File "/home/airflow/.local/lib/python3.12/site-packages/airflow/api_internal/internal_api_call.py", line 166, in wrapper
    return func(*args, **kwargs)
           ^^^^^^^^^^^^^^^^^^^^^
  File "/home/airflow/.local/lib/python3.12/site-packages/airflow/models/taskinstance.py", line 1216, in _handle_failure
    failure_context = TaskInstance.fetch_handle_failure_context(
                      ^^^^^^^^^^^^^^^^^^^^^^^^^^^^^^^^^^^^^^^^^^
  File "/home/airflow/.local/lib/python3.12/site-packages/airflow/models/taskinstance.py", line 3317, in fetch_handle_failure_context
    ti.refresh_from_db(session)
  File "/home/airflow/.local/lib/python3.12/site-packages/airflow/utils/session.py", line 94, in wrapper
    return func(*args, **kwargs)
           ^^^^^^^^^^^^^^^^^^^^^
  File "/home/airflow/.local/lib/python3.12/site-packages/airflow/models/taskinstance.py", line 2360, in refresh_from_db
    _refresh_from_db(task_instance=self, session=session, lock_for_update=lock_for_update)
  File "/home/airflow/.local/lib/python3.12/site-packages/airflow/models/taskinstance.py", line 873, in _refresh_from_db
    ti = TaskInstance.get_task_instance(
         ^^^^^^^^^^^^^^^^^^^^^^^^^^^^^^^
  File "/home/airflow/.local/lib/python3.12/site-packages/airflow/api_internal/internal_api_call.py", line 166, in wrapper
    return func(*args, **kwargs)
           ^^^^^^^^^^^^^^^^^^^^^
  File "/home/airflow/.local/lib/python3.12/site-packages/airflow/utils/session.py", line 94, in wrapper
    return func(*args, **kwargs)
           ^^^^^^^^^^^^^^^^^^^^^
  File "/home/airflow/.local/lib/python3.12/site-packages/airflow/models/taskinstance.py", line 2346, in get_task_instance
    return query.one_or_none()
           ^^^^^^^^^^^^^^^^^^^
  File "/home/airflow/.local/lib/python3.12/site-packages/sqlalchemy/orm/query.py", line 2850, in one_or_none
    return self._iter().one_or_none()
           ^^^^^^^^^^^^
  File "/home/airflow/.local/lib/python3.12/site-packages/sqlalchemy/orm/query.py", line 2916, in _iter
    result = self.session.execute(
             ^^^^^^^^^^^^^^^^^^^^^
  File "/home/airflow/.local/lib/python3.12/site-packages/sqlalchemy/orm/session.py", line 1716, in execute
    conn = self._connection_for_bind(bind)
           ^^^^^^^^^^^^^^^^^^^^^^^^^^^^^^^
  File "/home/airflow/.local/lib/python3.12/site-packages/sqlalchemy/orm/session.py", line 1555, in _connection_for_bind
    return self._transaction._connection_for_bind(
           ^^^^^^^^^^^^^^^^^^^^^^^^^^^^^^^^^^^^^^^
  File "/home/airflow/.local/lib/python3.12/site-packages/sqlalchemy/orm/session.py", line 750, in _connection_for_bind
    conn = bind.connect()
           ^^^^^^^^^^^^^^
  File "/home/airflow/.local/lib/python3.12/site-packages/sqlalchemy/future/engine.py", line 412, in connect
    return super(Engine, self).connect()
           ^^^^^^^^^^^^^^^^^^^^^^^^^^^^^
  File "/home/airflow/.local/lib/python3.12/site-packages/sqlalchemy/engine/base.py", line 3325, in connect
    return self._connection_cls(self, close_with_result=close_with_result)
           ^^^^^^^^^^^^^^^^^^^^^^^^^^^^^^^^^^^^^^^^^^^^^^^^^^^^^^^^^^^^^^^
  File "/home/airflow/.local/lib/python3.12/site-packages/sqlalchemy/engine/base.py", line 96, in __init__
    else engine.raw_connection()
         ^^^^^^^^^^^^^^^^^^^^^^^
  File "/home/airflow/.local/lib/python3.12/site-packages/sqlalchemy/engine/base.py", line 3404, in raw_connection
    return self._wrap_pool_connect(self.pool.connect, _connection)
           ^^^^^^^^^^^^^^^^^^^^^^^^^^^^^^^^^^^^^^^^^^^^^^^^^^^^^^^
  File "/home/airflow/.local/lib/python3.12/site-packages/sqlalchemy/engine/base.py", line 3374, in _wrap_pool_connect
    Connection._handle_dbapi_exception_noconnection(
  File "/home/airflow/.local/lib/python3.12/site-packages/sqlalchemy/engine/base.py", line 2208, in _handle_dbapi_exception_noconnection
    util.raise_(
  File "/home/airflow/.local/lib/python3.12/site-packages/sqlalchemy/util/compat.py", line 211, in raise_
    raise exception
  File "/home/airflow/.local/lib/python3.12/site-packages/sqlalchemy/engine/base.py", line 3371, in _wrap_pool_connect
    return fn()
           ^^^^
  File "/home/airflow/.local/lib/python3.12/site-packages/sqlalchemy/pool/base.py", line 327, in connect
    return _ConnectionFairy._checkout(self)
           ^^^^^^^^^^^^^^^^^^^^^^^^^^^^^^^^
  File "/home/airflow/.local/lib/python3.12/site-packages/sqlalchemy/pool/base.py", line 894, in _checkout
    fairy = _ConnectionRecord.checkout(pool)
            ^^^^^^^^^^^^^^^^^^^^^^^^^^^^^^^^
  File "/home/airflow/.local/lib/python3.12/site-packages/sqlalchemy/pool/base.py", line 493, in checkout
    rec = pool._do_get()
          ^^^^^^^^^^^^^^
  File "/home/airflow/.local/lib/python3.12/site-packages/sqlalchemy/pool/impl.py", line 256, in _do_get
    return self._create_connection()
           ^^^^^^^^^^^^^^^^^^^^^^^^^
  File "/home/airflow/.local/lib/python3.12/site-packages/sqlalchemy/pool/base.py", line 273, in _create_connection
    return _ConnectionRecord(self)
           ^^^^^^^^^^^^^^^^^^^^^^^
  File "/home/airflow/.local/lib/python3.12/site-packages/sqlalchemy/pool/base.py", line 388, in __init__
    self.__connect()
  File "/home/airflow/.local/lib/python3.12/site-packages/sqlalchemy/pool/base.py", line 690, in __connect
    with util.safe_reraise():
         ^^^^^^^^^^^^^^^^^^^
  File "/home/airflow/.local/lib/python3.12/site-packages/sqlalchemy/util/langhelpers.py", line 70, in __exit__
    compat.raise_(
  File "/home/airflow/.local/lib/python3.12/site-packages/sqlalchemy/util/compat.py", line 211, in raise_
    raise exception
  File "/home/airflow/.local/lib/python3.12/site-packages/sqlalchemy/pool/base.py", line 686, in __connect
    self.dbapi_connection = connection = pool._invoke_creator(self)
                                         ^^^^^^^^^^^^^^^^^^^^^^^^^^
  File "/home/airflow/.local/lib/python3.12/site-packages/sqlalchemy/engine/create.py", line 574, in connect
    return dialect.connect(*cargs, **cparams)
           ^^^^^^^^^^^^^^^^^^^^^^^^^^^^^^^^^^
  File "/home/airflow/.local/lib/python3.12/site-packages/sqlalchemy/engine/default.py", line 598, in connect
    return self.dbapi.connect(*cargs, **cparams)
           ^^^^^^^^^^^^^^^^^^^^^^^^^^^^^^^^^^^^^
  File "/home/airflow/.local/lib/python3.12/site-packages/psycopg2/__init__.py", line 122, in connect
    conn = _connect(dsn, connection_factory=connection_factory, **kwasync)
           ^^^^^^^^^^^^^^^^^^^^^^^^^^^^^^^^^^^^^^^^^^^^^^^^^^^^^^^^^^^^^^^
sqlalchemy.exc.OperationalError: (psycopg2.OperationalError) could not translate host name "postgres" to address: Temporary failure in name resolution

(Background on this error at: https://sqlalche.me/e/14/e3q8)
[2025-04-16T15:27:52.036+0000] {job.py:239} ERROR - Job heartbeat failed with error
Traceback (most recent call last):
  File "/home/airflow/.local/lib/python3.12/site-packages/sqlalchemy/engine/base.py", line 3371, in _wrap_pool_connect
    return fn()
           ^^^^
  File "/home/airflow/.local/lib/python3.12/site-packages/sqlalchemy/pool/base.py", line 327, in connect
    return _ConnectionFairy._checkout(self)
           ^^^^^^^^^^^^^^^^^^^^^^^^^^^^^^^^
  File "/home/airflow/.local/lib/python3.12/site-packages/sqlalchemy/pool/base.py", line 894, in _checkout
    fairy = _ConnectionRecord.checkout(pool)
            ^^^^^^^^^^^^^^^^^^^^^^^^^^^^^^^^
  File "/home/airflow/.local/lib/python3.12/site-packages/sqlalchemy/pool/base.py", line 493, in checkout
    rec = pool._do_get()
          ^^^^^^^^^^^^^^
  File "/home/airflow/.local/lib/python3.12/site-packages/sqlalchemy/pool/impl.py", line 256, in _do_get
    return self._create_connection()
           ^^^^^^^^^^^^^^^^^^^^^^^^^
  File "/home/airflow/.local/lib/python3.12/site-packages/sqlalchemy/pool/base.py", line 273, in _create_connection
    return _ConnectionRecord(self)
           ^^^^^^^^^^^^^^^^^^^^^^^
  File "/home/airflow/.local/lib/python3.12/site-packages/sqlalchemy/pool/base.py", line 388, in __init__
    self.__connect()
  File "/home/airflow/.local/lib/python3.12/site-packages/sqlalchemy/pool/base.py", line 690, in __connect
    with util.safe_reraise():
         ^^^^^^^^^^^^^^^^^^^
  File "/home/airflow/.local/lib/python3.12/site-packages/sqlalchemy/util/langhelpers.py", line 70, in __exit__
    compat.raise_(
  File "/home/airflow/.local/lib/python3.12/site-packages/sqlalchemy/util/compat.py", line 211, in raise_
    raise exception
  File "/home/airflow/.local/lib/python3.12/site-packages/sqlalchemy/pool/base.py", line 686, in __connect
    self.dbapi_connection = connection = pool._invoke_creator(self)
                                         ^^^^^^^^^^^^^^^^^^^^^^^^^^
  File "/home/airflow/.local/lib/python3.12/site-packages/sqlalchemy/engine/create.py", line 574, in connect
    return dialect.connect(*cargs, **cparams)
           ^^^^^^^^^^^^^^^^^^^^^^^^^^^^^^^^^^
  File "/home/airflow/.local/lib/python3.12/site-packages/sqlalchemy/engine/default.py", line 598, in connect
    return self.dbapi.connect(*cargs, **cparams)
           ^^^^^^^^^^^^^^^^^^^^^^^^^^^^^^^^^^^^^
  File "/home/airflow/.local/lib/python3.12/site-packages/psycopg2/__init__.py", line 122, in connect
    conn = _connect(dsn, connection_factory=connection_factory, **kwasync)
           ^^^^^^^^^^^^^^^^^^^^^^^^^^^^^^^^^^^^^^^^^^^^^^^^^^^^^^^^^^^^^^^
psycopg2.OperationalError: could not translate host name "postgres" to address: Temporary failure in name resolution


The above exception was the direct cause of the following exception:

Traceback (most recent call last):
  File "/home/airflow/.local/lib/python3.12/site-packages/airflow/jobs/job.py", line 207, in heartbeat
    self._merge_from(Job._fetch_from_db(self, session))
                     ^^^^^^^^^^^^^^^^^^^^^^^^^^^^^^^^^
  File "/home/airflow/.local/lib/python3.12/site-packages/airflow/api_internal/internal_api_call.py", line 166, in wrapper
    return func(*args, **kwargs)
           ^^^^^^^^^^^^^^^^^^^^^
  File "/home/airflow/.local/lib/python3.12/site-packages/airflow/utils/session.py", line 94, in wrapper
    return func(*args, **kwargs)
           ^^^^^^^^^^^^^^^^^^^^^
  File "/home/airflow/.local/lib/python3.12/site-packages/airflow/utils/retries.py", line 93, in wrapped_function
    for attempt in run_with_db_retries(max_retries=retries, logger=logger, **retry_kwargs):
                   ^^^^^^^^^^^^^^^^^^^^^^^^^^^^^^^^^^^^^^^^^^^^^^^^^^^^^^^^^^^^^^^^^^^^^^^
  File "/home/airflow/.local/lib/python3.12/site-packages/tenacity/__init__.py", line 443, in __iter__
    do = self.iter(retry_state=retry_state)
         ^^^^^^^^^^^^^^^^^^^^^^^^^^^^^^^^^^
  File "/home/airflow/.local/lib/python3.12/site-packages/tenacity/__init__.py", line 376, in iter
    result = action(retry_state)
             ^^^^^^^^^^^^^^^^^^^
  File "/home/airflow/.local/lib/python3.12/site-packages/tenacity/__init__.py", line 418, in exc_check
    raise retry_exc.reraise()
          ^^^^^^^^^^^^^^^^^^^
  File "/home/airflow/.local/lib/python3.12/site-packages/tenacity/__init__.py", line 185, in reraise
    raise self.last_attempt.result()
          ^^^^^^^^^^^^^^^^^^^^^^^^^^
  File "/usr/local/lib/python3.12/concurrent/futures/_base.py", line 449, in result
    return self.__get_result()
           ^^^^^^^^^^^^^^^^^^^
  File "/usr/local/lib/python3.12/concurrent/futures/_base.py", line 401, in __get_result
    raise self._exception
  File "/home/airflow/.local/lib/python3.12/site-packages/airflow/utils/retries.py", line 102, in wrapped_function
    return func(*args, **kwargs)
           ^^^^^^^^^^^^^^^^^^^^^
  File "/home/airflow/.local/lib/python3.12/site-packages/airflow/jobs/job.py", line 335, in _fetch_from_db
    session.merge(job)
  File "/home/airflow/.local/lib/python3.12/site-packages/sqlalchemy/orm/session.py", line 3056, in merge
    return self._merge(
           ^^^^^^^^^^^^
  File "/home/airflow/.local/lib/python3.12/site-packages/sqlalchemy/orm/session.py", line 3136, in _merge
    merged = self.get(
             ^^^^^^^^^
  File "/home/airflow/.local/lib/python3.12/site-packages/sqlalchemy/orm/session.py", line 2853, in get
    return self._get_impl(
           ^^^^^^^^^^^^^^^
  File "/home/airflow/.local/lib/python3.12/site-packages/sqlalchemy/orm/session.py", line 2975, in _get_impl
    return db_load_fn(
           ^^^^^^^^^^^
  File "/home/airflow/.local/lib/python3.12/site-packages/sqlalchemy/orm/loading.py", line 530, in load_on_pk_identity
    session.execute(
  File "/home/airflow/.local/lib/python3.12/site-packages/sqlalchemy/orm/session.py", line 1716, in execute
    conn = self._connection_for_bind(bind)
           ^^^^^^^^^^^^^^^^^^^^^^^^^^^^^^^
  File "/home/airflow/.local/lib/python3.12/site-packages/sqlalchemy/orm/session.py", line 1555, in _connection_for_bind
    return self._transaction._connection_for_bind(
           ^^^^^^^^^^^^^^^^^^^^^^^^^^^^^^^^^^^^^^^
  File "/home/airflow/.local/lib/python3.12/site-packages/sqlalchemy/orm/session.py", line 750, in _connection_for_bind
    conn = bind.connect()
           ^^^^^^^^^^^^^^
  File "/home/airflow/.local/lib/python3.12/site-packages/sqlalchemy/future/engine.py", line 412, in connect
    return super(Engine, self).connect()
           ^^^^^^^^^^^^^^^^^^^^^^^^^^^^^
  File "/home/airflow/.local/lib/python3.12/site-packages/sqlalchemy/engine/base.py", line 3325, in connect
    return self._connection_cls(self, close_with_result=close_with_result)
           ^^^^^^^^^^^^^^^^^^^^^^^^^^^^^^^^^^^^^^^^^^^^^^^^^^^^^^^^^^^^^^^
  File "/home/airflow/.local/lib/python3.12/site-packages/sqlalchemy/engine/base.py", line 96, in __init__
    else engine.raw_connection()
         ^^^^^^^^^^^^^^^^^^^^^^^
  File "/home/airflow/.local/lib/python3.12/site-packages/sqlalchemy/engine/base.py", line 3404, in raw_connection
    return self._wrap_pool_connect(self.pool.connect, _connection)
           ^^^^^^^^^^^^^^^^^^^^^^^^^^^^^^^^^^^^^^^^^^^^^^^^^^^^^^^
  File "/home/airflow/.local/lib/python3.12/site-packages/sqlalchemy/engine/base.py", line 3374, in _wrap_pool_connect
    Connection._handle_dbapi_exception_noconnection(
  File "/home/airflow/.local/lib/python3.12/site-packages/sqlalchemy/engine/base.py", line 2208, in _handle_dbapi_exception_noconnection
    util.raise_(
  File "/home/airflow/.local/lib/python3.12/site-packages/sqlalchemy/util/compat.py", line 211, in raise_
    raise exception
  File "/home/airflow/.local/lib/python3.12/site-packages/sqlalchemy/engine/base.py", line 3371, in _wrap_pool_connect
    return fn()
           ^^^^
  File "/home/airflow/.local/lib/python3.12/site-packages/sqlalchemy/pool/base.py", line 327, in connect
    return _ConnectionFairy._checkout(self)
           ^^^^^^^^^^^^^^^^^^^^^^^^^^^^^^^^
  File "/home/airflow/.local/lib/python3.12/site-packages/sqlalchemy/pool/base.py", line 894, in _checkout
    fairy = _ConnectionRecord.checkout(pool)
            ^^^^^^^^^^^^^^^^^^^^^^^^^^^^^^^^
  File "/home/airflow/.local/lib/python3.12/site-packages/sqlalchemy/pool/base.py", line 493, in checkout
    rec = pool._do_get()
          ^^^^^^^^^^^^^^
  File "/home/airflow/.local/lib/python3.12/site-packages/sqlalchemy/pool/impl.py", line 256, in _do_get
    return self._create_connection()
           ^^^^^^^^^^^^^^^^^^^^^^^^^
  File "/home/airflow/.local/lib/python3.12/site-packages/sqlalchemy/pool/base.py", line 273, in _create_connection
    return _ConnectionRecord(self)
           ^^^^^^^^^^^^^^^^^^^^^^^
  File "/home/airflow/.local/lib/python3.12/site-packages/sqlalchemy/pool/base.py", line 388, in __init__
    self.__connect()
  File "/home/airflow/.local/lib/python3.12/site-packages/sqlalchemy/pool/base.py", line 690, in __connect
    with util.safe_reraise():
         ^^^^^^^^^^^^^^^^^^^
  File "/home/airflow/.local/lib/python3.12/site-packages/sqlalchemy/util/langhelpers.py", line 70, in __exit__
    compat.raise_(
  File "/home/airflow/.local/lib/python3.12/site-packages/sqlalchemy/util/compat.py", line 211, in raise_
    raise exception
  File "/home/airflow/.local/lib/python3.12/site-packages/sqlalchemy/pool/base.py", line 686, in __connect
    self.dbapi_connection = connection = pool._invoke_creator(self)
                                         ^^^^^^^^^^^^^^^^^^^^^^^^^^
  File "/home/airflow/.local/lib/python3.12/site-packages/sqlalchemy/engine/create.py", line 574, in connect
    return dialect.connect(*cargs, **cparams)
           ^^^^^^^^^^^^^^^^^^^^^^^^^^^^^^^^^^
  File "/home/airflow/.local/lib/python3.12/site-packages/sqlalchemy/engine/default.py", line 598, in connect
    return self.dbapi.connect(*cargs, **cparams)
           ^^^^^^^^^^^^^^^^^^^^^^^^^^^^^^^^^^^^^
  File "/home/airflow/.local/lib/python3.12/site-packages/psycopg2/__init__.py", line 122, in connect
    conn = _connect(dsn, connection_factory=connection_factory, **kwasync)
           ^^^^^^^^^^^^^^^^^^^^^^^^^^^^^^^^^^^^^^^^^^^^^^^^^^^^^^^^^^^^^^^
sqlalchemy.exc.OperationalError: (psycopg2.OperationalError) could not translate host name "postgres" to address: Temporary failure in name resolution

(Background on this error at: https://sqlalche.me/e/14/e3q8)
[2025-04-16T15:28:20.235+0000] {job.py:254} ERROR - Job heartbeat failed with error. Scheduler is in unhealthy state
[2025-04-16T15:28:20.626+0000] {local_task_job_runner.py:266} INFO - Task exited with return code 1
[2025-04-16T15:28:24.979+0000] {standard_task_runner.py:217} INFO - Process not found (most likely exited), stop collecting metrics
[2025-04-16T15:28:26.109+0000] {local_task_job_runner.py:245} INFO - ::endgroup::
